Workbook

Sheet Porra_Grupos
B2: ⚽ PORRA MUNDIAL 2026 - FASE DE GRUPOS | J2: PARTICIPANTE: | K2: Tu Nombre Aqui
B3: Rellena los goles (celdas crema). Los partidos no jugados NO suman puntos ni goles automáticamente.
B5: 🏆 PREMIOS ESPECIALES DEL MUNDIAL | Q5: 📊 TOP 3º PUESTOS (MEJORES TERCEROS)
B6: Balon de Oro (Mejor Jugador) | D6: Escribe Jugador | Q6: Pos | R6: Equipo | S6: Pts | T6: GF | U6: DG
B7: Balon de Plata | D7: Escribe Jugador | Q7: 1 | R7: =Calculos_Internos!H160 | S7: =SUMIFS(Calculos_Internos!$C$160:$C$171, Calculos_Internos!$B$160:$B$171, R7) | T7: =SUMIFS(Calculos_Internos!$D$160:$D$171, Calculos_Internos!$B$160:$B$171, R7) | U7: =SUMIFS(Calculos_Internos!$E$160:$E$171, Calculos_Internos!$B$160:$B$171, R7)
B8: Balon de Bronce | D8: Escribe Jugador | Q8: 2 | R8: =Calculos_Internos!H161 | S8: =SUMIFS(Calculos_Internos!$C$160:$C$171, Calculos_Internos!$B$160:$B$171, R8) | T8: =SUMIFS(Calculos_Internos!$D$160:$D$171, Calculos_Internos!$B$160:$B$171, R8) | U8: =SUMIFS(Calculos_Internos!$E$160:$E$171, Calculos_Internos!$B$160:$B$171, R8)
B9: Maximo Goleador (Bota de Oro) | D9: Escribe Jugador | Q9: 3 | R9: =Calculos_Internos!H162 | S9: =SUMIFS(Calculos_Internos!$C$160:$C$171, Calculos_Internos!$B$160:$B$171, R9) | T9: =SUMIFS(Calculos_Internos!$D$160:$D$171, Calculos_Internos!$B$160:$B$171, R9) | U9: =SUMIFS(Calculos_Internos!$E$160:$E$171, Calculos_Internos!$B$160:$B$171, R9)
B10: Maximo Goleador (Plata) | D10: Escribe Jugador | Q10: 4 | R10: =Calculos_Internos!H163 | S10: =SUMIFS(Calculos_Internos!$C$160:$C$171, Calculos_Internos!$B$160:$B$171, R10) | T10: =SUMIFS(Calculos_Internos!$D$160:$D$171, Calculos_Internos!$B$160:$B$171, R10) | U10: =SUMIFS(Calculos_Internos!$E$160:$E$171, Calculos_Internos!$B$160:$B$171, R10)
B11: Maximo Goleador (Bronce) | D11: Escribe Jugador | Q11: 5 | R11: =Calculos_Internos!H164 | S11: =SUMIFS(Calculos_Internos!$C$160:$C$171, Calculos_Internos!$B$160:$B$171, R11) | T11: =SUMIFS(Calculos_Internos!$D$160:$D$171, Calculos_Internos!$B$160:$B$171, R11) | U11: =SUMIFS(Calculos_Internos!$E$160:$E$171, Calculos_Internos!$B$160:$B$171, R11)
Q12: 6 | R12: =Calculos_Internos!H165 | S12: =SUMIFS(Calculos_Internos!$C$160:$C$171, Calculos_Internos!$B$160:$B$171, R12) | T12: =SUMIFS(Calculos_Internos!$D$160:$D$171, Calculos_Internos!$B$160:$B$171, R12) | U12: =SUMIFS(Calculos_Internos!$E$160:$E$171, Calculos_Internos!$B$160:$B$171, R12)
Q13: 7 | R13: =Calculos_Internos!H166 | S13: =SUMIFS(Calculos_Internos!$C$160:$C$171, Calculos_Internos!$B$160:$B$171, R13) | T13: =SUMIFS(Calculos_Internos!$D$160:$D$171, Calculos_Internos!$B$160:$B$171, R13) | U13: =SUMIFS(Calculos_Internos!$E$160:$E$171, Calculos_Internos!$B$160:$B$171, R13)
B14: 📅 PARTIDOS GRUPO A | I14: 📊 CLASIFICACION GRUPO A | Q14: 8 | R14: =Calculos_Internos!H167 | S14: =SUMIFS(Calculos_Internos!$C$160:$C$171, Calculos_Internos!$B$160:$B$171, R14) | T14: =SUMIFS(Calculos_Internos!$D$160:$D$171, Calculos_Internos!$B$160:$B$171, R14) | U14: =SUMIFS(Calculos_Internos!$E$160:$E$171, Calculos_Internos!$B$160:$B$171, R14)
B15: M001 | C15: Mexico | E15: - | G15: Sudafrica | I15: Pos | J15: Equipo | K15: Pts | L15: GF | M15: GC | N15: DG | Q15: 9 | R15: =Calculos_Internos!H168 | S15: =SUMIFS(Calculos_Internos!$C$160:$C$171, Calculos_Internos!$B$160:$B$171, R15) | T15: =SUMIFS(Calculos_Internos!$D$160:$D$171, Calculos_Internos!$B$160:$B$171, R15) | U15: =SUMIFS(Calculos_Internos!$E$160:$E$171, Calculos_Internos!$B$160:$B$171, R15)
B16: M002 | C16: Corea del Sur | E16: - | G16: Rep. Checa | I16: 1 | J16: =Calculos_Internos!H81 | K16: =SUMIFS(Calculos_Internos!$B$81:$B$84, Calculos_Internos!$A$81:$A$84, J16) | L16: =SUMIFS(Calculos_Internos!$C$81:$C$84, Calculos_Internos!$A$81:$A$84, J16) | M16: =SUMIFS(Calculos_Internos!$D$81:$D$84, Calculos_Internos!$A$81:$A$84, J16) | N16: =SUMIFS(Calculos_Internos!$E$81:$E$84, Calculos_Internos!$A$81:$A$84, J16) | Q16: 10 | R16: =Calculos_Internos!H169 | S16: =SUMIFS(Calculos_Internos!$C$160:$C$171, Calculos_Internos!$B$160:$B$171, R16) | T16: =SUMIFS(Calculos_Internos!$D$160:$D$171, Calculos_Internos!$B$160:$B$171, R16) | U16: =SUMIFS(Calculos_Internos!$E$160:$E$171, Calculos_Internos!$B$160:$B$171, R16)
B17: M003 | C17: Mexico | E17: - | G17: Corea del Sur | I17: 2 | J17: =Calculos_Internos!H82 | K17: =SUMIFS(Calculos_Internos!$B$81:$B$84, Calculos_Internos!$A$81:$A$84, J17) | L17: =SUMIFS(Calculos_Internos!$C$81:$C$84, Calculos_Internos!$A$81:$A$84, J17) | M17: =SUMIFS(Calculos_Internos!$D$81:$D$84, Calculos_Internos!$A$81:$A$84, J17) | N17: =SUMIFS(Calculos_Internos!$E$81:$E$84, Calculos_Internos!$A$81:$A$84, J17) | Q17: 11 | R17: =Calculos_Internos!H170 | S17: =SUMIFS(Calculos_Internos!$C$160:$C$171, Calculos_Internos!$B$160:$B$171, R17) | T17: =SUMIFS(Calculos_Internos!$D$160:$D$171, Calculos_Internos!$B$160:$B$171, R17) | U17: =SUMIFS(Calculos_Internos!$E$160:$E$171, Calculos_Internos!$B$160:$B$171, R17)
B18: M004 | C18: Sudafrica | E18: - | G18: Rep. Checa | I18: 3 | J18: =Calculos_Internos!H83 | K18: =SUMIFS(Calculos_Internos!$B$81:$B$84, Calculos_Internos!$A$81:$A$84, J18) | L18: =SUMIFS(Calculos_Internos!$C$81:$C$84, Calculos_Internos!$A$81:$A$84, J18) | M18: =SUMIFS(Calculos_Internos!$D$81:$D$84, Calculos_Internos!$A$81:$A$84, J18) | N18: =SUMIFS(Calculos_Internos!$E$81:$E$84, Calculos_Internos!$A$81:$A$84, J18) | Q18: 12 | R18: =Calculos_Internos!H171 | S18: =SUMIFS(Calculos_Internos!$C$160:$C$171, Calculos_Internos!$B$160:$B$171, R18) | T18: =SUMIFS(Calculos_Internos!$D$160:$D$171, Calculos_Internos!$B$160:$B$171, R18) | U18: =SUMIFS(Calculos_Internos!$E$160:$E$171, Calculos_Internos!$B$160:$B$171, R18)
B19: M005 | C19: Rep. Checa | E19: - | G19: Mexico | I19: 4 | J19: =Calculos_Internos!H84 | K19: =SUMIFS(Calculos_Internos!$B$81:$B$84, Calculos_Internos!$A$81:$A$84, J19) | L19: =SUMIFS(Calculos_Internos!$C$81:$C$84, Calculos_Internos!$A$81:$A$84, J19) | M19: =SUMIFS(Calculos_Internos!$D$81:$D$84, Calculos_Internos!$A$81:$A$84, J19) | N19: =SUMIFS(Calculos_Internos!$E$81:$E$84, Calculos_Internos!$A$81:$A$84, J19)
B20: M006 | C20: Sudafrica | E20: - | G20: Corea del Sur
Q21: 🔥 ESTADÍSTICAS MÁXIMAS (SELECCIONES)
Q22: Categoría | S22: Selección | U22: Goles
B23: 📅 PARTIDOS GRUPO B | I23: 📊 CLASIFICACION GRUPO B | Q23: Más Goleadora (GF) | S23: =INDEX(Calculos_Internos!$A$81:$A$151, MATCH(MAX(Calculos_Internos!$L$81:$L$151), Calculos_Internos!$L$81:$L$151, 0)) | U23: =MAX(Calculos_Internos!$L$81:$L$151)
B24: M007 | C24: Canada | E24: - | G24: Bosnia y Herzegovina | I24: Pos | J24: Equipo | K24: Pts | L24: GF | M24: GC | N24: DG | Q24: Más Goleada (GC) | S24: =INDEX(Calculos_Internos!$A$81:$A$151, MATCH(MAX(Calculos_Internos!$M$81:$M$151), Calculos_Internos!$M$81:$M$151, 0)) | U24: =MAX(Calculos_Internos!$M$81:$M$151)
B25: M008 | C25: Catar | E25: - | G25: Suiza | I25: 1 | J25: =Calculos_Internos!H87 | K25: =SUMIFS(Calculos_Internos!$B$87:$B$90, Calculos_Internos!$A$87:$A$90, J25) | L25: =SUMIFS(Calculos_Internos!$C$87:$C$90, Calculos_Internos!$A$87:$A$90, J25) | M25: =SUMIFS(Calculos_Internos!$D$87:$D$90, Calculos_Internos!$A$87:$A$90, J25) | N25: =SUMIFS(Calculos_Internos!$E$87:$E$90, Calculos_Internos!$A$87:$A$90, J25)
B26: M009 | C26: Canada | E26: - | G26: Catar | I26: 2 | J26: =Calculos_Internos!H88 | K26: =SUMIFS(Calculos_Internos!$B$87:$B$90, Calculos_Internos!$A$87:$A$90, J26) | L26: =SUMIFS(Calculos_Internos!$C$87:$C$90, Calculos_Internos!$A$87:$A$90, J26) | M26: =SUMIFS(Calculos_Internos!$D$87:$D$90, Calculos_Internos!$A$87:$A$90, J26) | N26: =SUMIFS(Calculos_Internos!$E$87:$E$90, Calculos_Internos!$A$87:$A$90, J26)
B27: M010 | C27: Bosnia y Herzegovina | E27: - | G27: Suiza | I27: 3 | J27: =Calculos_Internos!H89 | K27: =SUMIFS(Calculos_Internos!$B$87:$B$90, Calculos_Internos!$A$87:$A$90, J27) | L27: =SUMIFS(Calculos_Internos!$C$87:$C$90, Calculos_Internos!$A$87:$A$90, J27) | M27: =SUMIFS(Calculos_Internos!$D$87:$D$90, Calculos_Internos!$A$87:$A$90, J27) | N27: =SUMIFS(Calculos_Internos!$E$87:$E$90, Calculos_Internos!$A$87:$A$90, J27)
B28: M011 | C28: Suiza | E28: - | G28: Canada | I28: 4 | J28: =Calculos_Internos!H90 | K28: =SUMIFS(Calculos_Internos!$B$87:$B$90, Calculos_Internos!$A$87:$A$90, J28) | L28: =SUMIFS(Calculos_Internos!$C$87:$C$90, Calculos_Internos!$A$87:$A$90, J28) | M28: =SUMIFS(Calculos_Internos!$D$87:$D$90, Calculos_Internos!$A$87:$A$90, J28) | N28: =SUMIFS(Calculos_Internos!$E$87:$E$90, Calculos_Internos!$A$87:$A$90, J28)
B29: M012 | C29: Bosnia y Herzegovina | E29: - | G29: Catar
B32: 📅 PARTIDOS GRUPO C | I32: 📊 CLASIFICACION GRUPO C
B33: M013 | C33: Brasil | E33: - | G33: Marruecos | I33: Pos | J33: Equipo | K33: Pts | L33: GF | M33: GC | N33: DG
B34: M014 | C34: Haiti | E34: - | G34: Escocia | I34: 1 | J34: =Calculos_Internos!H93 | K34: =SUMIFS(Calculos_Internos!$B$93:$B$96, Calculos_Internos!$A$93:$A$96, J34) | L34: =SUMIFS(Calculos_Internos!$C$93:$C$96, Calculos_Internos!$A$93:$A$96, J34) | M34: =SUMIFS(Calculos_Internos!$D$93:$D$96, Calculos_Internos!$A$93:$A$96, J34) | N34: =SUMIFS(Calculos_Internos!$E$93:$E$96, Calculos_Internos!$A$93:$A$96, J34)
B35: M015 | C35: Brasil | E35: - | G35: Haiti | I35: 2 | J35: =Calculos_Internos!H94 | K35: =SUMIFS(Calculos_Internos!$B$93:$B$96, Calculos_Internos!$A$93:$A$96, J35) | L35: =SUMIFS(Calculos_Internos!$C$93:$C$96, Calculos_Internos!$A$93:$A$96, J35) | M35: =SUMIFS(Calculos_Internos!$D$93:$D$96, Calculos_Internos!$A$93:$A$96, J35) | N35: =SUMIFS(Calculos_Internos!$E$93:$E$96, Calculos_Internos!$A$93:$A$96, J35)
B36: M016 | C36: Marruecos | E36: - | G36: Escocia | I36: 3 | J36: =Calculos_Internos!H95 | K36: =SUMIFS(Calculos_Internos!$B$93:$B$96, Calculos_Internos!$A$93:$A$96, J36) | L36: =SUMIFS(Calculos_Internos!$C$93:$C$96, Calculos_Internos!$A$93:$A$96, J36) | M36: =SUMIFS(Calculos_Internos!$D$93:$D$96, Calculos_Internos!$A$93:$A$96, J36) | N36: =SUMIFS(Calculos_Internos!$E$93:$E$96, Calculos_Internos!$A$93:$A$96, J36)
B37: M017 | C37: Escocia | E37: - | G37: Brasil | I37: 4 | J37: =Calculos_Internos!H96 | K37: =SUMIFS(Calculos_Internos!$B$93:$B$96, Calculos_Internos!$A$93:$A$96, J37) | L37: =SUMIFS(Calculos_Internos!$C$93:$C$96, Calculos_Internos!$A$93:$A$96, J37) | M37: =SUMIFS(Calculos_Internos!$D$93:$D$96, Calculos_Internos!$A$93:$A$96, J37) | N37: =SUMIFS(Calculos_Internos!$E$93:$E$96, Calculos_Internos!$A$93:$A$96, J37)
B38: M018 | C38: Marruecos | E38: - | G38: Haiti
B41: 📅 PARTIDOS GRUPO D | I41: 📊 CLASIFICACION GRUPO D
B42: M019 | C42: Estados Unidos | E42: - | G42: Paraguay | I42: Pos | J42: Equipo | K42: Pts | L42: GF | M42: GC | N42: DG
B43: M020 | C43: Australia | E43: - | G43: Turquia | I43: 1 | J43: =Calculos_Internos!H99 | K43: =SUMIFS(Calculos_Internos!$B$99:$B$102, Calculos_Internos!$A$99:$A$102, J43) | L43: =SUMIFS(Calculos_Internos!$C$99:$C$102, Calculos_Internos!$A$99:$A$102, J43) | M43: =SUMIFS(Calculos_Internos!$D$99:$D$102, Calculos_Internos!$A$99:$A$102, J43) | N43: =SUMIFS(Calculos_Internos!$E$99:$E$102, Calculos_Internos!$A$99:$A$102, J43)
B44: M021 | C44: Estados Unidos | E44: - | G44: Australia | I44: 2 | J44: =Calculos_Internos!H100 | K44: =SUMIFS(Calculos_Internos!$B$99:$B$102, Calculos_Internos!$A$99:$A$102, J44) | L44: =SUMIFS(Calculos_Internos!$C$99:$C$102, Calculos_Internos!$A$99:$A$102, J44) | M44: =SUMIFS(Calculos_Internos!$D$99:$D$102, Calculos_Internos!$A$99:$A$102, J44) | N44: =SUMIFS(Calculos_Internos!$E$99:$E$102, Calculos_Internos!$A$99:$A$102, J44)
B45: M022 | C45: Paraguay | E45: - | G45: Turquia | I45: 3 | J45: =Calculos_Internos!H101 | K45: =SUMIFS(Calculos_Internos!$B$99:$B$102, Calculos_Internos!$A$99:$A$102, J45) | L45: =SUMIFS(Calculos_Internos!$C$99:$C$102, Calculos_Internos!$A$99:$A$102, J45) | M45: =SUMIFS(Calculos_Internos!$D$99:$D$102, Calculos_Internos!$A$99:$A$102, J45) | N45: =SUMIFS(Calculos_Internos!$E$99:$E$102, Calculos_Internos!$A$99:$A$102, J45)
B46: M023 | C46: Turquia | E46: - | G46: Estados Unidos | I46: 4 | J46: =Calculos_Internos!H102 | K46: =SUMIFS(Calculos_Internos!$B$99:$B$102, Calculos_Internos!$A$99:$A$102, J46) | L46: =SUMIFS(Calculos_Internos!$C$99:$C$102, Calculos_Internos!$A$99:$A$102, J46) | M46: =SUMIFS(Calculos_Internos!$D$99:$D$102, Calculos_Internos!$A$99:$A$102, J46) | N46: =SUMIFS(Calculos_Internos!$E$99:$E$102, Calculos_Internos!$A$99:$A$102, J46)
...

Sheet Llave_Final
B2: 🏆 CUADRO DE ELIMINATORIAS DIRECTAS (MODO LLAVE)
B3: Los equipos bajan solos desde los grupos. Al lado de cada selección se muestra su origen explícito.
E4: Goles | F4: Pen. | K4: Goles | L4: Pen. | Q4: Goles | R4: Pen. | W4: Goles | X4: Pen. | AC4: Goles | AD4: Pen.
B5: DIECISEISAVOS DE FINAL | H5: OCTAVOS DE FINAL | N5: CUARTOS DE FINAL | T5: SEMIFINALES | Z5: GRANDES FINALES
B6: D1 (M73) | C6: 1A | D6: =Calculos_Internos!H81
C7: 3º Top 1 | D7: =Calculos_Internos!H160
H9: O1 (M89) | I9: Gan. D1 | J9: =Calculos_Internos!I200
I10: Gan. D2 | J10: =Calculos_Internos!I201
B12: D2 (M74) | C12: 2A | D12: =Calculos_Internos!H82
C13: 2B | D13: =Calculos_Internos!H88
N15: C1 (M97) | O15: Gan. O1 | P15: =Calculos_Internos!I216
O16: Gan. O2 | P16: =Calculos_Internos!I217
B18: D3 (M75) | C18: 1B | D18: =Calculos_Internos!H87
C19: 3º Top 2 | D19: =Calculos_Internos!H161
H21: O2 (M90) | I21: Gan. D3 | J21: =Calculos_Internos!I202
I22: Gan. D4 | J22: =Calculos_Internos!I203
B24: D4 (M76) | C24: 1C | D24: =Calculos_Internos!H93
C25: 3º Top 3 | D25: =Calculos_Internos!H162
T27: S1 (M101) | U27: Gan. C1 | V27: =Calculos_Internos!I224
U28: Gan. C2 | V28: =Calculos_Internos!I225
B30: D5 (M77) | C30: 2C | D30: =Calculos_Internos!H94
C31: 2D | D31: =Calculos_Internos!H100
H33: O3 (M91) | I33: Gan. D5 | J33: =Calculos_Internos!I204
I34: Gan. D6 | J34: =Calculos_Internos!I205
B36: D6 (M78) | C36: 1D | D36: =Calculos_Internos!H99
C37: 3º Top 4 | D37: =Calculos_Internos!H163
N39: C2 (M98) | O39: Gan. O3 | P39: =Calculos_Internos!I218
O40: Gan. O4 | P40: =Calculos_Internos!I219
B42: D7 (M79) | C42: 1E | D42: =Calculos_Internos!H105
C43: 3º Top 5 | D43: =Calculos_Internos!H164
H45: O4 (M92) | I45: Gan. D7 | J45: =Calculos_Internos!I206
I46: Gan. D8 | J46: =Calculos_Internos!I207 | Z46: M104 (Final) | AA46: Gan. S1 | AB46: =Calculos_Internos!I228
AA47: Gan. S2 | AB47: =Calculos_Internos!I229
B48: D8 (M80) | C48: 2E | D48: =Calculos_Internos!H106
C49: 2F | D49: =Calculos_Internos!H112
Z52: M103 (3º Puesto) | AA52: Perd. S1 | AB52: =IF(Calculos_Internos!I228=Calculos_Internos!C228,Calculos_Internos!F228,Calculos_Internos!C228)
N53: C3 (M99) | O53: Gan. O5 | P53: =Calculos_Internos!I220 | AA53: Perd. S2 | AB53: =IF(Calculos_Internos!I229=Calculos_Internos!C229,Calculos_Internos!F229,Calculos_Internos!C229)
B54: D9 (M81) | C54: 1F | D54: =Calculos_Internos!H111 | O54: Gan. O6 | P54: =Calculos_Internos!I221
C55: 3º Top 6 | D55: =Calculos_Internos!H165
H57: O5 (M93) | I57: Gan. D9 | J57: =Calculos_Internos!I208
...

Sheet Calculos_Internos
A1: ID | B1: Grupo | C1: Local | D1: GL | E1: GV | F1: Visitante | G1: PKL | H1: PKV | I1: Ganador | J1: PtsL | K1: PtsV | L1: GFL | M1: GFV
A2: M001 | B2: Grupo A | C2: =Porra_Grupos!C15 | D2: =IF(Porra_Grupos!D15="","",Porra_Grupos!D15) | E2: =IF(Porra_Grupos!F15="","",Porra_Grupos!F15) | F2: =Porra_Grupos!G15 | G2: - | H2: - | J2: =IF(OR(D2="",E2=""),0,IF(D2>E2,3,IF(D2=E2,1,0))) | K2: =IF(OR(D2="",E2=""),0,IF(E2>D2,3,IF(D2=E2,1,0))) | L2: =IF(OR(D2="",E2=""),0,D2) | M2: =IF(OR(D2="",E2=""),0,E2)
A3: M002 | B3: Grupo A | C3: =Porra_Grupos!C16 | D3: =IF(Porra_Grupos!D16="","",Porra_Grupos!D16) | E3: =IF(Porra_Grupos!F16="","",Porra_Grupos!F16) | F3: =Porra_Grupos!G16 | G3: - | H3: - | J3: =IF(OR(D3="",E3=""),0,IF(D3>E3,3,IF(D3=E3,1,0))) | K3: =IF(OR(D3="",E3=""),0,IF(E3>D3,3,IF(D3=E3,1,0))) | L3: =IF(OR(D3="",E3=""),0,D3) | M3: =IF(OR(D3="",E3=""),0,E3)
A4: M003 | B4: Grupo A | C4: =Porra_Grupos!C17 | D4: =IF(Porra_Grupos!D17="","",Porra_Grupos!D17) | E4: =IF(Porra_Grupos!F17="","",Porra_Grupos!F17) | F4: =Porra_Grupos!G17 | G4: - | H4: - | J4: =IF(OR(D4="",E4=""),0,IF(D4>E4,3,IF(D4=E4,1,0))) | K4: =IF(OR(D4="",E4=""),0,IF(E4>D4,3,IF(D4=E4,1,0))) | L4: =IF(OR(D4="",E4=""),0,D4) | M4: =IF(OR(D4="",E4=""),0,E4)
A5: M004 | B5: Grupo A | C5: =Porra_Grupos!C18 | D5: =IF(Porra_Grupos!D18="","",Porra_Grupos!D18) | E5: =IF(Porra_Grupos!F18="","",Porra_Grupos!F18) | F5: =Porra_Grupos!G18 | G5: - | H5: - | J5: =IF(OR(D5="",E5=""),0,IF(D5>E5,3,IF(D5=E5,1,0))) | K5: =IF(OR(D5="",E5=""),0,IF(E5>D5,3,IF(D5=E5,1,0))) | L5: =IF(OR(D5="",E5=""),0,D5) | M5: =IF(OR(D5="",E5=""),0,E5)
A6: M005 | B6: Grupo A | C6: =Porra_Grupos!C19 | D6: =IF(Porra_Grupos!D19="","",Porra_Grupos!D19) | E6: =IF(Porra_Grupos!F19="","",Porra_Grupos!F19) | F6: =Porra_Grupos!G19 | G6: - | H6: - | J6: =IF(OR(D6="",E6=""),0,IF(D6>E6,3,IF(D6=E6,1,0))) | K6: =IF(OR(D6="",E6=""),0,IF(E6>D6,3,IF(D6=E6,1,0))) | L6: =IF(OR(D6="",E6=""),0,D6) | M6: =IF(OR(D6="",E6=""),0,E6)
A7: M006 | B7: Grupo A | C7: =Porra_Grupos!C20 | D7: =IF(Porra_Grupos!D20="","",Porra_Grupos!D20) | E7: =IF(Porra_Grupos!F20="","",Porra_Grupos!F20) | F7: =Porra_Grupos!G20 | G7: - | H7: - | J7: =IF(OR(D7="",E7=""),0,IF(D7>E7,3,IF(D7=E7,1,0))) | K7: =IF(OR(D7="",E7=""),0,IF(E7>D7,3,IF(D7=E7,1,0))) | L7: =IF(OR(D7="",E7=""),0,D7) | M7: =IF(OR(D7="",E7=""),0,E7)
A8: M007 | B8: Grupo B | C8: =Porra_Grupos!C24 | D8: =IF(Porra_Grupos!D24="","",Porra_Grupos!D24) | E8: =IF(Porra_Grupos!F24="","",Porra_Grupos!F24) | F8: =Porra_Grupos!G24 | G8: - | H8: - | J8: =IF(OR(D8="",E8=""),0,IF(D8>E8,3,IF(D8=E8,1,0))) | K8: =IF(OR(D8="",E8=""),0,IF(E8>D8,3,IF(D8=E8,1,0))) | L8: =IF(OR(D8="",E8=""),0,D8) | M8: =IF(OR(D8="",E8=""),0,E8)
A9: M008 | B9: Grupo B | C9: =Porra_Grupos!C25 | D9: =IF(Porra_Grupos!D25="","",Porra_Grupos!D25) | E9: =IF(Porra_Grupos!F25="","",Porra_Grupos!F25) | F9: =Porra_Grupos!G25 | G9: - | H9: - | J9: =IF(OR(D9="",E9=""),0,IF(D9>E9,3,IF(D9=E9,1,0))) | K9: =IF(OR(D9="",E9=""),0,IF(E9>D9,3,IF(D9=E9,1,0))) | L9: =IF(OR(D9="",E9=""),0,D9) | M9: =IF(OR(D9="",E9=""),0,E9)
A10: M009 | B10: Grupo B | C10: =Porra_Grupos!C26 | D10: =IF(Porra_Grupos!D26="","",Porra_Grupos!D26) | E10: =IF(Porra_Grupos!F26="","",Porra_Grupos!F26) | F10: =Porra_Grupos!G26 | G10: - | H10: - | J10: =IF(OR(D10="",E10=""),0,IF(D10>E10,3,IF(D10=E10,1,0))) | K10: =IF(OR(D10="",E10=""),0,IF(E10>D10,3,IF(D10=E10,1,0))) | L10: =IF(OR(D10="",E10=""),0,D10) | M10: =IF(OR(D10="",E10=""),0,E10)
A11: M010 | B11: Grupo B | C11: =Porra_Grupos!C27 | D11: =IF(Porra_Grupos!D27="","",Porra_Grupos!D27) | E11: =IF(Porra_Grupos!F27="","",Porra_Grupos!F27) | F11: =Porra_Grupos!G27 | G11: - | H11: - | J11: =IF(OR(D11="",E11=""),0,IF(D11>E11,3,IF(D11=E11,1,0))) | K11: =IF(OR(D11="",E11=""),0,IF(E11>D11,3,IF(D11=E11,1,0))) | L11: =IF(OR(D11="",E11=""),0,D11) | M11: =IF(OR(D11="",E11=""),0,E11)
A12: M011 | B12: Grupo B | C12: =Porra_Grupos!C28 | D12: =IF(Porra_Grupos!D28="","",Porra_Grupos!D28) | E12: =IF(Porra_Grupos!F28="","",Porra_Grupos!F28) | F12: =Porra_Grupos!G28 | G12: - | H12: - | J12: =IF(OR(D12="",E12=""),0,IF(D12>E12,3,IF(D12=E12,1,0))) | K12: =IF(OR(D12="",E12=""),0,IF(E12>D12,3,IF(D12=E12,1,0))) | L12: =IF(OR(D12="",E12=""),0,D12) | M12: =IF(OR(D12="",E12=""),0,E12)
A13: M012 | B13: Grupo B | C13: =Porra_Grupos!C29 | D13: =IF(Porra_Grupos!D29="","",Porra_Grupos!D29) | E13: =IF(Porra_Grupos!F29="","",Porra_Grupos!F29) | F13: =Porra_Grupos!G29 | G13: - | H13: - | J13: =IF(OR(D13="",E13=""),0,IF(D13>E13,3,IF(D13=E13,1,0))) | K13: =IF(OR(D13="",E13=""),0,IF(E13>D13,3,IF(D13=E13,1,0))) | L13: =IF(OR(D13="",E13=""),0,D13) | M13: =IF(OR(D13="",E13=""),0,E13)
A14: M013 | B14: Grupo C | C14: =Porra_Grupos!C33 | D14: =IF(Porra_Grupos!D33="","",Porra_Grupos!D33) | E14: =IF(Porra_Grupos!F33="","",Porra_Grupos!F33) | F14: =Porra_Grupos!G33 | G14: - | H14: - | J14: =IF(OR(D14="",E14=""),0,IF(D14>E14,3,IF(D14=E14,1,0))) | K14: =IF(OR(D14="",E14=""),0,IF(E14>D14,3,IF(D14=E14,1,0))) | L14: =IF(OR(D14="",E14=""),0,D14) | M14: =IF(OR(D14="",E14=""),0,E14)
A15: M014 | B15: Grupo C | C15: =Porra_Grupos!C34 | D15: =IF(Porra_Grupos!D34="","",Porra_Grupos!D34) | E15: =IF(Porra_Grupos!F34="","",Porra_Grupos!F34) | F15: =Porra_Grupos!G34 | G15: - | H15: - | J15: =IF(OR(D15="",E15=""),0,IF(D15>E15,3,IF(D15=E15,1,0))) | K15: =IF(OR(D15="",E15=""),0,IF(E15>D15,3,IF(D15=E15,1,0))) | L15: =IF(OR(D15="",E15=""),0,D15) | M15: =IF(OR(D15="",E15=""),0,E15)
A16: M015 | B16: Grupo C | C16: =Porra_Grupos!C35 | D16: =IF(Porra_Grupos!D35="","",Porra_Grupos!D35) | E16: =IF(Porra_Grupos!F35="","",Porra_Grupos!F35) | F16: =Porra_Grupos!G35 | G16: - | H16: - | J16: =IF(OR(D16="",E16=""),0,IF(D16>E16,3,IF(D16=E16,1,0))) | K16: =IF(OR(D16="",E16=""),0,IF(E16>D16,3,IF(D16=E16,1,0))) | L16: =IF(OR(D16="",E16=""),0,D16) | M16: =IF(OR(D16="",E16=""),0,E16)
A17: M016 | B17: Grupo C | C17: =Porra_Grupos!C36 | D17: =IF(Porra_Grupos!D36="","",Porra_Grupos!D36) | E17: =IF(Porra_Grupos!F36="","",Porra_Grupos!F36) | F17: =Porra_Grupos!G36 | G17: - | H17: - | J17: =IF(OR(D17="",E17=""),0,IF(D17>E17,3,IF(D17=E17,1,0))) | K17: =IF(OR(D17="",E17=""),0,IF(E17>D17,3,IF(D17=E17,1,0))) | L17: =IF(OR(D17="",E17=""),0,D17) | M17: =IF(OR(D17="",E17=""),0,E17)
A18: M017 | B18: Grupo C | C18: =Porra_Grupos!C37 | D18: =IF(Porra_Grupos!D37="","",Porra_Grupos!D37) | E18: =IF(Porra_Grupos!F37="","",Porra_Grupos!F37) | F18: =Porra_Grupos!G37 | G18: - | H18: - | J18: =IF(OR(D18="",E18=""),0,IF(D18>E18,3,IF(D18=E18,1,0))) | K18: =IF(OR(D18="",E18=""),0,IF(E18>D18,3,IF(D18=E18,1,0))) | L18: =IF(OR(D18="",E18=""),0,D18) | M18: =IF(OR(D18="",E18=""),0,E18)
A19: M018 | B19: Grupo C | C19: =Porra_Grupos!C38 | D19: =IF(Porra_Grupos!D38="","",Porra_Grupos!D38) | E19: =IF(Porra_Grupos!F38="","",Porra_Grupos!F38) | F19: =Porra_Grupos!G38 | G19: - | H19: - | J19: =IF(OR(D19="",E19=""),0,IF(D19>E19,3,IF(D19=E19,1,0))) | K19: =IF(OR(D19="",E19=""),0,IF(E19>D19,3,IF(D19=E19,1,0))) | L19: =IF(OR(D19="",E19=""),0,D19) | M19: =IF(OR(D19="",E19=""),0,E19)
A20: M019 | B20: Grupo D | C20: =Porra_Grupos!C42 | D20: =IF(Porra_Grupos!D42="","",Porra_Grupos!D42) | E20: =IF(Porra_Grupos!F42="","",Porra_Grupos!F42) | F20: =Porra_Grupos!G42 | G20: - | H20: - | J20: =IF(OR(D20="",E20=""),0,IF(D20>E20,3,IF(D20=E20,1,0))) | K20: =IF(OR(D20="",E20=""),0,IF(E20>D20,3,IF(D20=E20,1,0))) | L20: =IF(OR(D20="",E20=""),0,D20) | M20: =IF(OR(D20="",E20=""),0,E20)
A21: M020 | B21: Grupo D | C21: =Porra_Grupos!C43 | D21: =IF(Porra_Grupos!D43="","",Porra_Grupos!D43) | E21: =IF(Porra_Grupos!F43="","",Porra_Grupos!F43) | F21: =Porra_Grupos!G43 | G21: - | H21: - | J21: =IF(OR(D21="",E21=""),0,IF(D21>E21,3,IF(D21=E21,1,0))) | K21: =IF(OR(D21="",E21=""),0,IF(E21>D21,3,IF(D21=E21,1,0))) | L21: =IF(OR(D21="",E21=""),0,D21) | M21: =IF(OR(D21="",E21=""),0,E21)
A22: M021 | B22: Grupo D | C22: =Porra_Grupos!C44 | D22: =IF(Porra_Grupos!D44="","",Porra_Grupos!D44) | E22: =IF(Porra_Grupos!F44="","",Porra_Grupos!F44) | F22: =Porra_Grupos!G44 | G22: - | H22: - | J22: =IF(OR(D22="",E22=""),0,IF(D22>E22,3,IF(D22=E22,1,0))) | K22: =IF(OR(D22="",E22=""),0,IF(E22>D22,3,IF(D22=E22,1,0))) | L22: =IF(OR(D22="",E22=""),0,D22) | M22: =IF(OR(D22="",E22=""),0,E22)
A23: M022 | B23: Grupo D | C23: =Porra_Grupos!C45 | D23: =IF(Porra_Grupos!D45="","",Porra_Grupos!D45) | E23: =IF(Porra_Grupos!F45="","",Porra_Grupos!F45) | F23: =Porra_Grupos!G45 | G23: - | H23: - | J23: =IF(OR(D23="",E23=""),0,IF(D23>E23,3,IF(D23=E23,1,0))) | K23: =IF(OR(D23="",E23=""),0,IF(E23>D23,3,IF(D23=E23,1,0))) | L23: =IF(OR(D23="",E23=""),0,D23) | M23: =IF(OR(D23="",E23=""),0,E23)
A24: M023 | B24: Grupo D | C24: =Porra_Grupos!C46 | D24: =IF(Porra_Grupos!D46="","",Porra_Grupos!D46) | E24: =IF(Porra_Grupos!F46="","",Porra_Grupos!F46) | F24: =Porra_Grupos!G46 | G24: - | H24: - | J24: =IF(OR(D24="",E24=""),0,IF(D24>E24,3,IF(D24=E24,1,0))) | K24: =IF(OR(D24="",E24=""),0,IF(E24>D24,3,IF(D24=E24,1,0))) | L24: =IF(OR(D24="",E24=""),0,D24) | M24: =IF(OR(D24="",E24=""),0,E24)
A25: M024 | B25: Grupo D | C25: =Porra_Grupos!C47 | D25: =IF(Porra_Grupos!D47="","",Porra_Grupos!D47) | E25: =IF(Porra_Grupos!F47="","",Porra_Grupos!F47) | F25: =Porra_Grupos!G47 | G25: - | H25: - | J25: =IF(OR(D25="",E25=""),0,IF(D25>E25,3,IF(D25=E25,1,0))) | K25: =IF(OR(D25="",E25=""),0,IF(E25>D25,3,IF(D25=E25,1,0))) | L25: =IF(OR(D25="",E25=""),0,D25) | M25: =IF(OR(D25="",E25=""),0,E25)
A26: M025 | B26: Grupo E | C26: =Porra_Grupos!C51 | D26: =IF(Porra_Grupos!D51="","",Porra_Grupos!D51) | E26: =IF(Porra_Grupos!F51="","",Porra_Grupos!F51) | F26: =Porra_Grupos!G51 | G26: - | H26: - | J26: =IF(OR(D26="",E26=""),0,IF(D26>E26,3,IF(D26=E26,1,0))) | K26: =IF(OR(D26="",E26=""),0,IF(E26>D26,3,IF(D26=E26,1,0))) | L26: =IF(OR(D26="",E26=""),0,D26) | M26: =IF(OR(D26="",E26=""),0,E26)
A27: M026 | B27: Grupo E | C27: =Porra_Grupos!C52 | D27: =IF(Porra_Grupos!D52="","",Porra_Grupos!D52) | E27: =IF(Porra_Grupos!F52="","",Porra_Grupos!F52) | F27: =Porra_Grupos!G52 | G27: - | H27: - | J27: =IF(OR(D27="",E27=""),0,IF(D27>E27,3,IF(D27=E27,1,0))) | K27: =IF(OR(D27="",E27=""),0,IF(E27>D27,3,IF(D27=E27,1,0))) | L27: =IF(OR(D27="",E27=""),0,D27) | M27: =IF(OR(D27="",E27=""),0,E27)
A28: M027 | B28: Grupo E | C28: =Porra_Grupos!C53 | D28: =IF(Porra_Grupos!D53="","",Porra_Grupos!D53) | E28: =IF(Porra_Grupos!F53="","",Porra_Grupos!F53) | F28: =Porra_Grupos!G53 | G28: - | H28: - | J28: =IF(OR(D28="",E28=""),0,IF(D28>E28,3,IF(D28=E28,1,0))) | K28: =IF(OR(D28="",E28=""),0,IF(E28>D28,3,IF(D28=E28,1,0))) | L28: =IF(OR(D28="",E28=""),0,D28) | M28: =IF(OR(D28="",E28=""),0,E28)
A29: M028 | B29: Grupo E | C29: =Porra_Grupos!C54 | D29: =IF(Porra_Grupos!D54="","",Porra_Grupos!D54) | E29: =IF(Porra_Grupos!F54="","",Porra_Grupos!F54) | F29: =Porra_Grupos!G54 | G29: - | H29: - | J29: =IF(OR(D29="",E29=""),0,IF(D29>E29,3,IF(D29=E29,1,0))) | K29: =IF(OR(D29="",E29=""),0,IF(E29>D29,3,IF(D29=E29,1,0))) | L29: =IF(OR(D29="",E29=""),0,D29) | M29: =IF(OR(D29="",E29=""),0,E29)
A30: M029 | B30: Grupo E | C30: =Porra_Grupos!C55 | D30: =IF(Porra_Grupos!D55="","",Porra_Grupos!D55) | E30: =IF(Porra_Grupos!F55="","",Porra_Grupos!F55) | F30: =Porra_Grupos!G55 | G30: - | H30: - | J30: =IF(OR(D30="",E30=""),0,IF(D30>E30,3,IF(D30=E30,1,0))) | K30: =IF(OR(D30="",E30=""),0,IF(E30>D30,3,IF(D30=E30,1,0))) | L30: =IF(OR(D30="",E30=""),0,D30) | M30: =IF(OR(D30="",E30=""),0,E30)
A31: M030 | B31: Grupo E | C31: =Porra_Grupos!C56 | D31: =IF(Porra_Grupos!D56="","",Porra_Grupos!D56) | E31: =IF(Porra_Grupos!F56="","",Porra_Grupos!F56) | F31: =Porra_Grupos!G56 | G31: - | H31: - | J31: =IF(OR(D31="",E31=""),0,IF(D31>E31,3,IF(D31=E31,1,0))) | K31: =IF(OR(D31="",E31=""),0,IF(E31>D31,3,IF(D31=E31,1,0))) | L31: =IF(OR(D31="",E31=""),0,D31) | M31: =IF(OR(D31="",E31=""),0,E31)
A32: M031 | B32: Grupo F | C32: =Porra_Grupos!C60 | D32: =IF(Porra_Grupos!D60="","",Porra_Grupos!D60) | E32: =IF(Porra_Grupos!F60="","",Porra_Grupos!F60) | F32: =Porra_Grupos!G60 | G32: - | H32: - | J32: =IF(OR(D32="",E32=""),0,IF(D32>E32,3,IF(D32=E32,1,0))) | K32: =IF(OR(D32="",E32=""),0,IF(E32>D32,3,IF(D32=E32,1,0))) | L32: =IF(OR(D32="",E32=""),0,D32) | M32: =IF(OR(D32="",E32=""),0,E32)
A33: M032 | B33: Grupo F | C33: =Porra_Grupos!C61 | D33: =IF(Porra_Grupos!D61="","",Porra_Grupos!D61) | E33: =IF(Porra_Grupos!F61="","",Porra_Grupos!F61) | F33: =Porra_Grupos!G61 | G33: - | H33: - | J33: =IF(OR(D33="",E33=""),0,IF(D33>E33,3,IF(D33=E33,1,0))) | K33: =IF(OR(D33="",E33=""),0,IF(E33>D33,3,IF(D33=E33,1,0))) | L33: =IF(OR(D33="",E33=""),0,D33) | M33: =IF(OR(D33="",E33=""),0,E33)
A34: M033 | B34: Grupo F | C34: =Porra_Grupos!C62 | D34: =IF(Porra_Grupos!D62="","",Porra_Grupos!D62) | E34: =IF(Porra_Grupos!F62="","",Porra_Grupos!F62) | F34: =Porra_Grupos!G62 | G34: - | H34: - | J34: =IF(OR(D34="",E34=""),0,IF(D34>E34,3,IF(D34=E34,1,0))) | K34: =IF(OR(D34="",E34=""),0,IF(E34>D34,3,IF(D34=E34,1,0))) | L34: =IF(OR(D34="",E34=""),0,D34) | M34: =IF(OR(D34="",E34=""),0,E34)
A35: M034 | B35: Grupo F | C35: =Porra_Grupos!C63 | D35: =IF(Porra_Grupos!D63="","",Porra_Grupos!D63) | E35: =IF(Porra_Grupos!F63="","",Porra_Grupos!F63) | F35: =Porra_Grupos!G63 | G35: - | H35: - | J35: =IF(OR(D35="",E35=""),0,IF(D35>E35,3,IF(D35=E35,1,0))) | K35: =IF(OR(D35="",E35=""),0,IF(E35>D35,3,IF(D35=E35,1,0))) | L35: =IF(OR(D35="",E35=""),0,D35) | M35: =IF(OR(D35="",E35=""),0,E35)
A36: M035 | B36: Grupo F | C36: =Porra_Grupos!C64 | D36: =IF(Porra_Grupos!D64="","",Porra_Grupos!D64) | E36: =IF(Porra_Grupos!F64="","",Porra_Grupos!F64) | F36: =Porra_Grupos!G64 | G36: - | H36: - | J36: =IF(OR(D36="",E36=""),0,IF(D36>E36,3,IF(D36=E36,1,0))) | K36: =IF(OR(D36="",E36=""),0,IF(E36>D36,3,IF(D36=E36,1,0))) | L36: =IF(OR(D36="",E36=""),0,D36) | M36: =IF(OR(D36="",E36=""),0,E36)
A37: M036 | B37: Grupo F | C37: =Porra_Grupos!C65 | D37: =IF(Porra_Grupos!D65="","",Porra_Grupos!D65) | E37: =IF(Porra_Grupos!F65="","",Porra_Grupos!F65) | F37: =Porra_Grupos!G65 | G37: - | H37: - | J37: =IF(OR(D37="",E37=""),0,IF(D37>E37,3,IF(D37=E37,1,0))) | K37: =IF(OR(D37="",E37=""),0,IF(E37>D37,3,IF(D37=E37,1,0))) | L37: =IF(OR(D37="",E37=""),0,D37) | M37: =IF(OR(D37="",E37=""),0,E37)
A38: M037 | B38: Grupo G | C38: =Porra_Grupos!C69 | D38: =IF(Porra_Grupos!D69="","",Porra_Grupos!D69) | E38: =IF(Porra_Grupos!F69="","",Porra_Grupos!F69) | F38: =Porra_Grupos!G69 | G38: - | H38: - | J38: =IF(OR(D38="",E38=""),0,IF(D38>E38,3,IF(D38=E38,1,0))) | K38: =IF(OR(D38="",E38=""),0,IF(E38>D38,3,IF(D38=E38,1,0))) | L38: =IF(OR(D38="",E38=""),0,D38) | M38: =IF(OR(D38="",E38=""),0,E38)
A39: M038 | B39: Grupo G | C39: =Porra_Grupos!C70 | D39: =IF(Porra_Grupos!D70="","",Porra_Grupos!D70) | E39: =IF(Porra_Grupos!F70="","",Porra_Grupos!F70) | F39: =Porra_Grupos!G70 | G39: - | H39: - | J39: =IF(OR(D39="",E39=""),0,IF(D39>E39,3,IF(D39=E39,1,0))) | K39: =IF(OR(D39="",E39=""),0,IF(E39>D39,3,IF(D39=E39,1,0))) | L39: =IF(OR(D39="",E39=""),0,D39) | M39: =IF(OR(D39="",E39=""),0,E39)
A40: M039 | B40: Grupo G | C40: =Porra_Grupos!C71 | D40: =IF(Porra_Grupos!D71="","",Porra_Grupos!D71) | E40: =IF(Porra_Grupos!F71="","",Porra_Grupos!F71) | F40: =Porra_Grupos!G71 | G40: - | H40: - | J40: =IF(OR(D40="",E40=""),0,IF(D40>E40,3,IF(D40=E40,1,0))) | K40: =IF(OR(D40="",E40=""),0,IF(E40>D40,3,IF(D40=E40,1,0))) | L40: =IF(OR(D40="",E40=""),0,D40) | M40: =IF(OR(D40="",E40=""),0,E40)
...

Sheet Datos_Raw
A1: Participante | B1: ID Partido | C1: Fase | D1: Equipo Local | E1: Equipo Visitante | F1: Goles Local | G1: Goles Visitante | H1: Penaltis Local | I1: Penaltis Visitante | J1: Balon Oro | K1: Balon Plata | L1: Balon Bronce | M1: Goleador 1 | N1: Goleador 2 | O1: Goleador 3
A2: =Porra_Grupos!$K$2 | B2: =Calculos_Internos!A2 | C2: =Calculos_Internos!B2 | D2: =Calculos_Internos!C2 | E2: =Calculos_Internos!F2 | F2: =Calculos_Internos!D2 | G2: =Calculos_Internos!E2 | H2: =IF(Calculos_Internos!G2="-", "-", Calculos_Internos!G2) | I2: =IF(Calculos_Internos!H2="-", "-", Calculos_Internos!H2) | J2: =Porra_Grupos!$D$6 | K2: =Porra_Grupos!$D$7 | L2: =Porra_Grupos!$D$8 | M2: =Porra_Grupos!$D$9 | N2: =Porra_Grupos!$D$10 | O2: =Porra_Grupos!$D$11
A3: =Porra_Grupos!$K$2 | B3: =Calculos_Internos!A3 | C3: =Calculos_Internos!B3 | D3: =Calculos_Internos!C3 | E3: =Calculos_Internos!F3 | F3: =Calculos_Internos!D3 | G3: =Calculos_Internos!E3 | H3: =IF(Calculos_Internos!G3="-", "-", Calculos_Internos!G3) | I3: =IF(Calculos_Internos!H3="-", "-", Calculos_Internos!H3) | J3: =Porra_Grupos!$D$6 | K3: =Porra_Grupos!$D$7 | L3: =Porra_Grupos!$D$8 | M3: =Porra_Grupos!$D$9 | N3: =Porra_Grupos!$D$10 | O3: =Porra_Grupos!$D$11
A4: =Porra_Grupos!$K$2 | B4: =Calculos_Internos!A4 | C4: =Calculos_Internos!B4 | D4: =Calculos_Internos!C4 | E4: =Calculos_Internos!F4 | F4: =Calculos_Internos!D4 | G4: =Calculos_Internos!E4 | H4: =IF(Calculos_Internos!G4="-", "-", Calculos_Internos!G4) | I4: =IF(Calculos_Internos!H4="-", "-", Calculos_Internos!H4) | J4: =Porra_Grupos!$D$6 | K4: =Porra_Grupos!$D$7 | L4: =Porra_Grupos!$D$8 | M4: =Porra_Grupos!$D$9 | N4: =Porra_Grupos!$D$10 | O4: =Porra_Grupos!$D$11
A5: =Porra_Grupos!$K$2 | B5: =Calculos_Internos!A5 | C5: =Calculos_Internos!B5 | D5: =Calculos_Internos!C5 | E5: =Calculos_Internos!F5 | F5: =Calculos_Internos!D5 | G5: =Calculos_Internos!E5 | H5: =IF(Calculos_Internos!G5="-", "-", Calculos_Internos!G5) | I5: =IF(Calculos_Internos!H5="-", "-", Calculos_Internos!H5) | J5: =Porra_Grupos!$D$6 | K5: =Porra_Grupos!$D$7 | L5: =Porra_Grupos!$D$8 | M5: =Porra_Grupos!$D$9 | N5: =Porra_Grupos!$D$10 | O5: =Porra_Grupos!$D$11
A6: =Porra_Grupos!$K$2 | B6: =Calculos_Internos!A6 | C6: =Calculos_Internos!B6 | D6: =Calculos_Internos!C6 | E6: =Calculos_Internos!F6 | F6: =Calculos_Internos!D6 | G6: =Calculos_Internos!E6 | H6: =IF(Calculos_Internos!G6="-", "-", Calculos_Internos!G6) | I6: =IF(Calculos_Internos!H6="-", "-", Calculos_Internos!H6) | J6: =Porra_Grupos!$D$6 | K6: =Porra_Grupos!$D$7 | L6: =Porra_Grupos!$D$8 | M6: =Porra_Grupos!$D$9 | N6: =Porra_Grupos!$D$10 | O6: =Porra_Grupos!$D$11
A7: =Porra_Grupos!$K$2 | B7: =Calculos_Internos!A7 | C7: =Calculos_Internos!B7 | D7: =Calculos_Internos!C7 | E7: =Calculos_Internos!F7 | F7: =Calculos_Internos!D7 | G7: =Calculos_Internos!E7 | H7: =IF(Calculos_Internos!G7="-", "-", Calculos_Internos!G7) | I7: =IF(Calculos_Internos!H7="-", "-", Calculos_Internos!H7) | J7: =Porra_Grupos!$D$6 | K7: =Porra_Grupos!$D$7 | L7: =Porra_Grupos!$D$8 | M7: =Porra_Grupos!$D$9 | N7: =Porra_Grupos!$D$10 | O7: =Porra_Grupos!$D$11
A8: =Porra_Grupos!$K$2 | B8: =Calculos_Internos!A8 | C8: =Calculos_Internos!B8 | D8: =Calculos_Internos!C8 | E8: =Calculos_Internos!F8 | F8: =Calculos_Internos!D8 | G8: =Calculos_Internos!E8 | H8: =IF(Calculos_Internos!G8="-", "-", Calculos_Internos!G8) | I8: =IF(Calculos_Internos!H8="-", "-", Calculos_Internos!H8) | J8: =Porra_Grupos!$D$6 | K8: =Porra_Grupos!$D$7 | L8: =Porra_Grupos!$D$8 | M8: =Porra_Grupos!$D$9 | N8: =Porra_Grupos!$D$10 | O8: =Porra_Grupos!$D$11
A9: =Porra_Grupos!$K$2 | B9: =Calculos_Internos!A9 | C9: =Calculos_Internos!B9 | D9: =Calculos_Internos!C9 | E9: =Calculos_Internos!F9 | F9: =Calculos_Internos!D9 | G9: =Calculos_Internos!E9 | H9: =IF(Calculos_Internos!G9="-", "-", Calculos_Internos!G9) | I9: =IF(Calculos_Internos!H9="-", "-", Calculos_Internos!H9) | J9: =Porra_Grupos!$D$6 | K9: =Porra_Grupos!$D$7 | L9: =Porra_Grupos!$D$8 | M9: =Porra_Grupos!$D$9 | N9: =Porra_Grupos!$D$10 | O9: =Porra_Grupos!$D$11
A10: =Porra_Grupos!$K$2 | B10: =Calculos_Internos!A10 | C10: =Calculos_Internos!B10 | D10: =Calculos_Internos!C10 | E10: =Calculos_Internos!F10 | F10: =Calculos_Internos!D10 | G10: =Calculos_Internos!E10 | H10: =IF(Calculos_Internos!G10="-", "-", Calculos_Internos!G10) | I10: =IF(Calculos_Internos!H10="-", "-", Calculos_Internos!H10) | J10: =Porra_Grupos!$D$6 | K10: =Porra_Grupos!$D$7 | L10: =Porra_Grupos!$D$8 | M10: =Porra_Grupos!$D$9 | N10: =Porra_Grupos!$D$10 | O10: =Porra_Grupos!$D$11
A11: =Porra_Grupos!$K$2 | B11: =Calculos_Internos!A11 | C11: =Calculos_Internos!B11 | D11: =Calculos_Internos!C11 | E11: =Calculos_Internos!F11 | F11: =Calculos_Internos!D11 | G11: =Calculos_Internos!E11 | H11: =IF(Calculos_Internos!G11="-", "-", Calculos_Internos!G11) | I11: =IF(Calculos_Internos!H11="-", "-", Calculos_Internos!H11) | J11: =Porra_Grupos!$D$6 | K11: =Porra_Grupos!$D$7 | L11: =Porra_Grupos!$D$8 | M11: =Porra_Grupos!$D$9 | N11: =Porra_Grupos!$D$10 | O11: =Porra_Grupos!$D$11
A12: =Porra_Grupos!$K$2 | B12: =Calculos_Internos!A12 | C12: =Calculos_Internos!B12 | D12: =Calculos_Internos!C12 | E12: =Calculos_Internos!F12 | F12: =Calculos_Internos!D12 | G12: =Calculos_Internos!E12 | H12: =IF(Calculos_Internos!G12="-", "-", Calculos_Internos!G12) | I12: =IF(Calculos_Internos!H12="-", "-", Calculos_Internos!H12) | J12: =Porra_Grupos!$D$6 | K12: =Porra_Grupos!$D$7 | L12: =Porra_Grupos!$D$8 | M12: =Porra_Grupos!$D$9 | N12: =Porra_Grupos!$D$10 | O12: =Porra_Grupos!$D$11
A13: =Porra_Grupos!$K$2 | B13: =Calculos_Internos!A13 | C13: =Calculos_Internos!B13 | D13: =Calculos_Internos!C13 | E13: =Calculos_Internos!F13 | F13: =Calculos_Internos!D13 | G13: =Calculos_Internos!E13 | H13: =IF(Calculos_Internos!G13="-", "-", Calculos_Internos!G13) | I13: =IF(Calculos_Internos!H13="-", "-", Calculos_Internos!H13) | J13: =Porra_Grupos!$D$6 | K13: =Porra_Grupos!$D$7 | L13: =Porra_Grupos!$D$8 | M13: =Porra_Grupos!$D$9 | N13: =Porra_Grupos!$D$10 | O13: =Porra_Grupos!$D$11
... A73: =Porra_Grupos!$K$2 | B73: =Calculos_Internos!A73 | C73: =Calculos_Internos!B73 | D73: =Calculos_Internos!C73 | E73: =Calculos_Internos!F73 | F73: =Calculos_Internos!D73 | G73: =Calculos_Internos!E73 | H73: =IF(Calculos_Internos!G73="-", "-", Calculos_Internos!G73) | I73: =IF(Calculos_Internos!H73="-", "-", Calculos_Internos!H73) | J73: =Porra_Grupos!$D$6 | K73: =Porra_Grupos!$D$7 | L73: =Porra_Grupos!$D$8 | M73: =Porra_Grupos!$D$9 | N73: =Porra_Grupos!$D$10 | O73: =Porra_Grupos!$D$11
A74: =Porra_Grupos!$K$2 | B74: =Calculos_Internos!A200 | C74: =Calculos_Internos!B200 | D74: =Calculos_Internos!C200 | E74: =Calculos_Internos!F200 | F74: =Calculos_Internos!D200 | G74: =Calculos_Internos!E200 | H74: =IF(Calculos_Internos!G200="-", "-", Calculos_Internos!G200) | I74: =IF(Calculos_Internos!H200="-", "-", Calculos_Internos!H200) | J74: =Porra_Grupos!$D$6 | K74: =Porra_Grupos!$D$7 | L74: =Porra_Grupos!$D$8 | M74: =Porra_Grupos!$D$9 | N74: =Porra_Grupos!$D$10 | O74: =Porra_Grupos!$D$11
A75: =Porra_Grupos!$K$2 | B75: =Calculos_Internos!A201 | C75: =Calculos_Internos!B201 | D75: =Calculos_Internos!C201 | E75: =Calculos_Internos!F201 | F75: =Calculos_Internos!D201 | G75: =Calculos_Internos!E201 | H75: =IF(Calculos_Internos!G201="-", "-", Calculos_Internos!G201) | I75: =IF(Calculos_Internos!H201="-", "-", Calculos_Internos!H201) | J75: =Porra_Grupos!$D$6 | K75: =Porra_Grupos!$D$7 | L75: =Porra_Grupos!$D$8 | M75: =Porra_Grupos!$D$9 | N75: =Porra_Grupos!$D$10 | O75: =Porra_Grupos!$D$11
A76: =Porra_Grupos!$K$2 | B76: =Calculos_Internos!A202 | C76: =Calculos_Internos!B202 | D76: =Calculos_Internos!C202 | E76: =Calculos_Internos!F202 | F76: =Calculos_Internos!D202 | G76: =Calculos_Internos!E202 | H76: =IF(Calculos_Internos!G202="-", "-", Calculos_Internos!G202) | I76: =IF(Calculos_Internos!H202="-", "-", Calculos_Internos!H202) | J76: =Porra_Grupos!$D$6 | K76: =Porra_Grupos!$D$7 | L76: =Porra_Grupos!$D$8 | M76: =Porra_Grupos!$D$9 | N76: =Porra_Grupos!$D$10 | O76: =Porra_Grupos!$D$11
A77: =Porra_Grupos!$K$2 | B77: =Calculos_Internos!A203 | C77: =Calculos_Internos!B203 | D77: =Calculos_Internos!C203 | E77: =Calculos_Internos!F203 | F77: =Calculos_Internos!D203 | G77: =Calculos_Internos!E203 | H77: =IF(Calculos_Internos!G203="-", "-", Calculos_Internos!G203) | I77: =IF(Calculos_Internos!H203="-", "-", Calculos_Internos!H203) | J77: =Porra_Grupos!$D$6 | K77: =Porra_Grupos!$D$7 | L77: =Porra_Grupos!$D$8 | M77: =Porra_Grupos!$D$9 | N77: =Porra_Grupos!$D$10 | O77: =Porra_Grupos!$D$11
A78: =Porra_Grupos!$K$2 | B78: =Calculos_Internos!A204 | C78: =Calculos_Internos!B204 | D78: =Calculos_Internos!C204 | E78: =Calculos_Internos!F204 | F78: =Calculos_Internos!D204 | G78: =Calculos_Internos!E204 | H78: =IF(Calculos_Internos!G204="-", "-", Calculos_Internos!G204) | I78: =IF(Calculos_Internos!H204="-", "-", Calculos_Internos!H204) | J78: =Porra_Grupos!$D$6 | K78: =Porra_Grupos!$D$7 | L78: =Porra_Grupos!$D$8 | M78: =Porra_Grupos!$D$9 | N78: =Porra_Grupos!$D$10 | O78: =Porra_Grupos!$D$11
A79: =Porra_Grupos!$K$2 | B79: =Calculos_Internos!A205 | C79: =Calculos_Internos!B205 | D79: =Calculos_Internos!C205 | E79: =Calculos_Internos!F205 | F79: =Calculos_Internos!D205 | G79: =Calculos_Internos!E205 | H79: =IF(Calculos_Internos!G205="-", "-", Calculos_Internos!G205) | I79: =IF(Calculos_Internos!H205="-", "-", Calculos_Internos!H205) | J79: =Porra_Grupos!$D$6 | K79: =Porra_Grupos!$D$7 | L79: =Porra_Grupos!$D$8 | M79: =Porra_Grupos!$D$9 | N79: =Porra_Grupos!$D$10 | O79: =Porra_Grupos!$D$11
A80: =Porra_Grupos!$K$2 | B80: =Calculos_Internos!A206 | C80: =Calculos_Internos!B206 | D80: =Calculos_Internos!C206 | E80: =Calculos_Internos!F206 | F80: =Calculos_Internos!D206 | G80: =Calculos_Internos!E206 | H80: =IF(Calculos_Internos!G206="-", "-", Calculos_Internos!G206) | I80: =IF(Calculos_Internos!H206="-", "-", Calculos_Internos!H206) | J80: =Porra_Grupos!$D$6 | K80: =Porra_Grupos!$D$7 | L80: =Porra_Grupos!$D$8 | M80: =Porra_Grupos!$D$9 | N80: =Porra_Grupos!$D$10 | O80: =Porra_Grupos!$D$11
A81: =Porra_Grupos!$K$2 | B81: =Calculos_Internos!A207 | C81: =Calculos_Internos!B207 | D81: =Calculos_Internos!C207 | E81: =Calculos_Internos!F207 | F81: =Calculos_Internos!D207 | G81: =Calculos_Internos!E207 | H81: =IF(Calculos_Internos!G207="-", "-", Calculos_Internos!G207) | I81: =IF(Calculos_Internos!H207="-", "-", Calculos_Internos!H207) | J81: =Porra_Grupos!$D$6 | K81: =Porra_Grupos!$D$7 | L81: =Porra_Grupos!$D$8 | M81: =Porra_Grupos!$D$9 | N81: =Porra_Grupos!$D$10 | O81: =Porra_Grupos!$D$11
A82: =Porra_Grupos!$K$2 | B82: =Calculos_Internos!A208 | C82: =Calculos_Internos!B208 | D82: =Calculos_Internos!C208 | E82: =Calculos_Internos!F208 | F82: =Calculos_Internos!D208 | G82: =Calculos_Internos!E208 | H82: =IF(Calculos_Internos!G208="-", "-", Calculos_Internos!G208) | I82: =IF(Calculos_Internos!H208="-", "-", Calculos_Internos!H208) | J82: =Porra_Grupos!$D$6 | K82: =Porra_Grupos!$D$7 | L82: =Porra_Grupos!$D$8 | M82: =Porra_Grupos!$D$9 | N82: =Porra_Grupos!$D$10 | O82: =Porra_Grupos!$D$11
A83: =Porra_Grupos!$K$2 | B83: =Calculos_Internos!A209 | C83: =Calculos_Internos!B209 | D83: =Calculos_Internos!C209 | E83: =Calculos_Internos!F209 | F83: =Calculos_Internos!D209 | G83: =Calculos_Internos!E209 | H83: =IF(Calculos_Internos!G209="-", "-", Calculos_Internos!G209) | I83: =IF(Calculos_Internos!H209="-", "-", Calculos_Internos!H209) | J83: =Porra_Grupos!$D$6 | K83: =Porra_Grupos!$D$7 | L83: =Porra_Grupos!$D$8 | M83: =Porra_Grupos!$D$9 | N83: =Porra_Grupos!$D$10 | O83: =Porra_Grupos!$D$11
A84: =Porra_Grupos!$K$2 | B84: =Calculos_Internos!A210 | C84: =Calculos_Internos!B210 | D84: =Calculos_Internos!C210 | E84: =Calculos_Internos!F210 | F84: =Calculos_Internos!D210 | G84: =Calculos_Internos!E210 | H84: =IF(Calculos_Internos!G210="-", "-", Calculos_Internos!G210) | I84: =IF(Calculos_Internos!H210="-", "-", Calculos_Internos!H210) | J84: =Porra_Grupos!$D$6 | K84: =Porra_Grupos!$D$7 | L84: =Porra_Grupos!$D$8 | M84: =Porra_Grupos!$D$9 | N84: =Porra_Grupos!$D$10 | O84: =Porra_Grupos!$D$11
A85: =Porra_Grupos!$K$2 | B85: =Calculos_Internos!A211 | C85: =Calculos_Internos!B211 | D85: =Calculos_Internos!C211 | E85: =Calculos_Internos!F211 | F85: =Calculos_Internos!D211 | G85: =Calculos_Internos!E211 | H85: =IF(Calculos_Internos!G211="-", "-", Calculos_Internos!G211) | I85: =IF(Calculos_Internos!H211="-", "-", Calculos_Internos!H211) | J85: =Porra_Grupos!$D$6 | K85: =Porra_Grupos!$D$7 | L85: =Porra_Grupos!$D$8 | M85: =Porra_Grupos!$D$9 | N85: =Porra_Grupos!$D$10 | O85: =Porra_Grupos!$D$11
... A105: =Porra_Grupos!$K$2 | B105: =Calculos_Internos!A231 | C105: =Calculos_Internos!B231 | D105: =Calculos_Internos!C231 | E105: =Calculos_Internos!F231 | F105: =Calculos_Internos!D231 | G105: =Calculos_Internos!E231 | H105: =IF(Calculos_Internos!G231="-", "-", Calculos_Internos!G231) | I105: =IF(Calculos_Internos!H231="-", "-", Calculos_Internos!H231) | J105: =Porra_Grupos!$D$6 | K105: =Porra_Grupos!$D$7 | L105: =Porra_Grupos!$D$8 | M105: =Porra_Grupos!$D$9 | N105: =Porra_Grupos!$D$10 | O105: =Porra_Grupos!$D$11
