Workbook

Sheet Configuracion
A1: CONFIGURACIÓN DE PUNTOS Y PREMIOS DE LA PORRA
A3: Categoría | B3: Puntos
A4: Acierto Ganador / Empate (Resultado 1X2) | B4: 1
A5: Acierto Marcador Exacto (Goles) | B5: 3
A6: Acierto Balón de Oro | B6: 10
A7: Acierto Balón de Plata | B7: 5
A8: Acierto Balón de Bronce | B8: 3
A9: Acierto Bota de Oro | B9: 10
A10: Acierto Bota de Plata | B10: 5
A11: Acierto Bota de Bronce | B11: 3
A14: RESULTADOS OFICIALES PREMIOS MUNDIAL
A16: Premio Especial | B16: Ganador Real (Escribe a mano)
A17: Ganador Balón de Oro (Mejor Jugador)
A18: Ganador Balón de Plata
A19: Ganador Balón de Bronce
A20: Ganador Bota de Oro (Máximo Goleador)
A21: Ganador Bota de Plata
A22: Ganador Bota de Bronce

Sheet Resultados_Reales
A1: RESULTADOS REALES DEL MUNDIAL 2026
A3: ID Partido | B3: Fase | C3: Local | D3: Visitante | E3: Goles Local | F3: Goles Visitante | G3: Penaltis Local | H3: Penaltis Visitante | I3: Ganador Oficial
A4: M001 | B4: Grupo A | C4: Mexico | D4: Sudafrica | I4: =IF(OR(E4="",F4=""),"",IF(E4>F4,C4,IF(F4>E4,D4,IF(OR(G4="-",G4=""),"Empate",IF(G4>H4,C4,D4)))))
A5: M002 | B5: Grupo A | C5: Corea del Sur | D5: Rep. Checa | I5: =IF(OR(E5="",F5=""),"",IF(E5>F5,C5,IF(F5>E5,D5,IF(OR(G5="-",G5=""),"Empate",IF(G5>H5,C5,D5)))))
A6: M003 | B6: Grupo A | C6: Mexico | D6: Corea del Sur | I6: =IF(OR(E6="",F6=""),"",IF(E6>F6,C6,IF(F6>E6,D6,IF(OR(G6="-",G6=""),"Empate",IF(G6>H6,C6,D6)))))
A7: M004 | B7: Grupo A | C7: Sudafrica | D7: Rep. Checa | I7: =IF(OR(E7="",F7=""),"",IF(E7>F7,C7,IF(F7>E7,D7,IF(OR(G7="-",G7=""),"Empate",IF(G7>H7,C7,D7)))))
A8: M005 | B8: Grupo A | C8: Rep. Checa | D8: Mexico | I8: =IF(OR(E8="",F8=""),"",IF(E8>F8,C8,IF(F8>E8,D8,IF(OR(G8="-",G8=""),"Empate",IF(G8>H8,C8,D8)))))
A9: M006 | B9: Grupo A | C9: Sudafrica | D9: Corea del Sur | I9: =IF(OR(E9="",F9=""),"",IF(E9>F9,C9,IF(F9>E9,D9,IF(OR(G9="-",G9=""),"Empate",IF(G9>H9,C9,D9)))))
A10: M007 | B10: Grupo B | C10: Canada | D10: Bosnia y Herzegovina | I10: =IF(OR(E10="",F10=""),"",IF(E10>F10,C10,IF(F10>E10,D10,IF(OR(G10="-",G10=""),"Empate",IF(G10>H10,C10,D10)))))
A11: M008 | B11: Grupo B | C11: Catar | D11: Suiza | I11: =IF(OR(E11="",F11=""),"",IF(E11>F11,C11,IF(F11>E11,D11,IF(OR(G11="-",G11=""),"Empate",IF(G11>H11,C11,D11)))))
A12: M009 | B12: Grupo B | C12: Canada | D12: Catar | I12: =IF(OR(E12="",F12=""),"",IF(E12>F12,C12,IF(F12>E12,D12,IF(OR(G12="-",G12=""),"Empate",IF(G12>H12,C12,D12)))))
A13: M010 | B13: Grupo B | C13: Bosnia y Herzegovina | D13: Suiza | I13: =IF(OR(E13="",F13=""),"",IF(E13>F13,C13,IF(F13>E13,D13,IF(OR(G13="-",G13=""),"Empate",IF(G13>H13,C13,D13)))))
A14: M011 | B14: Grupo B | C14: Suiza | D14: Canada | I14: =IF(OR(E14="",F14=""),"",IF(E14>F14,C14,IF(F14>E14,D14,IF(OR(G14="-",G14=""),"Empate",IF(G14>H14,C14,D14)))))
A15: M012 | B15: Grupo B | C15: Bosnia y Herzegovina | D15: Catar | I15: =IF(OR(E15="",F15=""),"",IF(E15>F15,C15,IF(F15>E15,D15,IF(OR(G15="-",G15=""),"Empate",IF(G15>H15,C15,D15)))))
... A107: M104 | B107: Finales | C107: Local M104 | D107: Visitante M104 | I107: =IF(OR(E107="",F107=""),"",IF(E107>F107,C107,IF(F107>E107,D107,IF(OR(G107="-",G107=""),"Empate",IF(G107>H107,C107,D107)))))

Sheet Predicciones_Master
A1: BASE DE DATOS DE PREDICCIONES IMPORTADAS
A3: Clave (Helper) | B3: Participante | C3: ID Partido | D3: Fase | E3: Local | F3: Visitante | G3: GL Pred | H3: GV Pred | I3: PKL Pred | J3: PKV Pred | K3: Puntos Ganados | L3: Balón Oro | M3: Balón Plata | N3: Balón Bronce | O3: Bota Oro | P3: Bota Plata | Q3: Bota Bronce
A4: =B4&"_"&C4 | K4: =IF(OR(ISERROR(VLOOKUP(C4, Resultados_Reales!$A$4:$I$107, 5, FALSE)), ISERROR(VLOOKUP(C4, Resultados_Reales!$A$4:$I$107, 6, FALSE)), VLOOKUP(C4, Resultados_Reales!$A$4:$I$107, 5, FALSE)="", VLOOKUP(C4, Resultados_Reales!$A$4:$I$107, 6, FALSE)=""), 0, IF(AND(VLOOKUP(C4, Resultados_Reales!$A$4:$I$107, 5, FALSE)=G4, VLOOKUP(C4, Resultados_Reales!$A$4:$I$107, 6, FALSE)=H4), Configuracion!$B$5, IF(SIGN(VLOOKUP(C4, Resultados_Reales!$A$4:$I$107, 5, FALSE)-VLOOKUP(C4, Resultados_Reales!$A$4:$I$107, 6, FALSE)) = SIGN(G4-H4), Configuracion!$B$4, 0)))
A5: =B5&"_"&C5 | K5: =IF(OR(ISERROR(VLOOKUP(C5, Resultados_Reales!$A$4:$I$107, 5, FALSE)), ISERROR(VLOOKUP(C5, Resultados_Reales!$A$4:$I$107, 6, FALSE)), VLOOKUP(C5, Resultados_Reales!$A$4:$I$107, 5, FALSE)="", VLOOKUP(C5, Resultados_Reales!$A$4:$I$107, 6, FALSE)=""), 0, IF(AND(VLOOKUP(C5, Resultados_Reales!$A$4:$I$107, 5, FALSE)=G5, VLOOKUP(C5, Resultados_Reales!$A$4:$I$107, 6, FALSE)=H5), Configuracion!$B$5, IF(SIGN(VLOOKUP(C5, Resultados_Reales!$A$4:$I$107, 5, FALSE)-VLOOKUP(C5, Resultados_Reales!$A$4:$I$107, 6, FALSE)) = SIGN(G5-H5), Configuracion!$B$4, 0)))
A6: =B6&"_"&C6 | K6: =IF(OR(ISERROR(VLOOKUP(C6, Resultados_Reales!$A$4:$I$107, 5, FALSE)), ISERROR(VLOOKUP(C6, Resultados_Reales!$A$4:$I$107, 6, FALSE)), VLOOKUP(C6, Resultados_Reales!$A$4:$I$107, 5, FALSE)="", VLOOKUP(C6, Resultados_Reales!$A$4:$I$107, 6, FALSE)=""), 0, IF(AND(VLOOKUP(C6, Resultados_Reales!$A$4:$I$107, 5, FALSE)=G6, VLOOKUP(C6, Resultados_Reales!$A$4:$I$107, 6, FALSE)=H6), Configuracion!$B$5, IF(SIGN(VLOOKUP(C6, Resultados_Reales!$A$4:$I$107, 5, FALSE)-VLOOKUP(C6, Resultados_Reales!$A$4:$I$107, 6, FALSE)) = SIGN(G6-H6), Configuracion!$B$4, 0)))
A7: =B7&"_"&C7 | K7: =IF(OR(ISERROR(VLOOKUP(C7, Resultados_Reales!$A$4:$I$107, 5, FALSE)), ISERROR(VLOOKUP(C7, Resultados_Reales!$A$4:$I$107, 6, FALSE)), VLOOKUP(C7, Resultados_Reales!$A$4:$I$107, 5, FALSE)="", VLOOKUP(C7, Resultados_Reales!$A$4:$I$107, 6, FALSE)=""), 0, IF(AND(VLOOKUP(C7, Resultados_Reales!$A$4:$I$107, 5, FALSE)=G7, VLOOKUP(C7, Resultados_Reales!$A$4:$I$107, 6, FALSE)=H7), Configuracion!$B$5, IF(SIGN(VLOOKUP(C7, Resultados_Reales!$A$4:$I$107, 5, FALSE)-VLOOKUP(C7, Resultados_Reales!$A$4:$I$107, 6, FALSE)) = SIGN(G7-H7), Configuracion!$B$4, 0)))
A8: =B8&"_"&C8 | K8: =IF(OR(ISERROR(VLOOKUP(C8, Resultados_Reales!$A$4:$I$107, 5, FALSE)), ISERROR(VLOOKUP(C8, Resultados_Reales!$A$4:$I$107, 6, FALSE)), VLOOKUP(C8, Resultados_Reales!$A$4:$I$107, 5, FALSE)="", VLOOKUP(C8, Resultados_Reales!$A$4:$I$107, 6, FALSE)=""), 0, IF(AND(VLOOKUP(C8, Resultados_Reales!$A$4:$I$107, 5, FALSE)=G8, VLOOKUP(C8, Resultados_Reales!$A$4:$I$107, 6, FALSE)=H8), Configuracion!$B$5, IF(SIGN(VLOOKUP(C8, Resultados_Reales!$A$4:$I$107, 5, FALSE)-VLOOKUP(C8, Resultados_Reales!$A$4:$I$107, 6, FALSE)) = SIGN(G8-H8), Configuracion!$B$4, 0)))
A9: =B9&"_"&C9 | K9: =IF(OR(ISERROR(VLOOKUP(C9, Resultados_Reales!$A$4:$I$107, 5, FALSE)), ISERROR(VLOOKUP(C9, Resultados_Reales!$A$4:$I$107, 6, FALSE)), VLOOKUP(C9, Resultados_Reales!$A$4:$I$107, 5, FALSE)="", VLOOKUP(C9, Resultados_Reales!$A$4:$I$107, 6, FALSE)=""), 0, IF(AND(VLOOKUP(C9, Resultados_Reales!$A$4:$I$107, 5, FALSE)=G9, VLOOKUP(C9, Resultados_Reales!$A$4:$I$107, 6, FALSE)=H9), Configuracion!$B$5, IF(SIGN(VLOOKUP(C9, Resultados_Reales!$A$4:$I$107, 5, FALSE)-VLOOKUP(C9, Resultados_Reales!$A$4:$I$107, 6, FALSE)) = SIGN(G9-H9), Configuracion!$B$4, 0)))
A10: =B10&"_"&C10 | K10: =IF(OR(ISERROR(VLOOKUP(C10, Resultados_Reales!$A$4:$I$107, 5, FALSE)), ISERROR(VLOOKUP(C10, Resultados_Reales!$A$4:$I$107, 6, FALSE)), VLOOKUP(C10, Resultados_Reales!$A$4:$I$107, 5, FALSE)="", VLOOKUP(C10, Resultados_Reales!$A$4:$I$107, 6, FALSE)=""), 0, IF(AND(VLOOKUP(C10, Resultados_Reales!$A$4:$I$107, 5, FALSE)=G10, VLOOKUP(C10, Resultados_Reales!$A$4:$I$107, 6, FALSE)=H10), Configuracion!$B$5, IF(SIGN(VLOOKUP(C10, Resultados_Reales!$A$4:$I$107, 5, FALSE)-VLOOKUP(C10, Resultados_Reales!$A$4:$I$107, 6, FALSE)) = SIGN(G10-H10), Configuracion!$B$4, 0)))
A11: =B11&"_"&C11 | K11: =IF(OR(ISERROR(VLOOKUP(C11, Resultados_Reales!$A$4:$I$107, 5, FALSE)), ISERROR(VLOOKUP(C11, Resultados_Reales!$A$4:$I$107, 6, FALSE)), VLOOKUP(C11, Resultados_Reales!$A$4:$I$107, 5, FALSE)="", VLOOKUP(C11, Resultados_Reales!$A$4:$I$107, 6, FALSE)=""), 0, IF(AND(VLOOKUP(C11, Resultados_Reales!$A$4:$I$107, 5, FALSE)=G11, VLOOKUP(C11, Resultados_Reales!$A$4:$I$107, 6, FALSE)=H11), Configuracion!$B$5, IF(SIGN(VLOOKUP(C11, Resultados_Reales!$A$4:$I$107, 5, FALSE)-VLOOKUP(C11, Resultados_Reales!$A$4:$I$107, 6, FALSE)) = SIGN(G11-H11), Configuracion!$B$4, 0)))
A12: =B12&"_"&C12 | K12: =IF(OR(ISERROR(VLOOKUP(C12, Resultados_Reales!$A$4:$I$107, 5, FALSE)), ISERROR(VLOOKUP(C12, Resultados_Reales!$A$4:$I$107, 6, FALSE)), VLOOKUP(C12, Resultados_Reales!$A$4:$I$107, 5, FALSE)="", VLOOKUP(C12, Resultados_Reales!$A$4:$I$107, 6, FALSE)=""), 0, IF(AND(VLOOKUP(C12, Resultados_Reales!$A$4:$I$107, 5, FALSE)=G12, VLOOKUP(C12, Resultados_Reales!$A$4:$I$107, 6, FALSE)=H12), Configuracion!$B$5, IF(SIGN(VLOOKUP(C12, Resultados_Reales!$A$4:$I$107, 5, FALSE)-VLOOKUP(C12, Resultados_Reales!$A$4:$I$107, 6, FALSE)) = SIGN(G12-H12), Configuracion!$B$4, 0)))
A13: =B13&"_"&C13 | K13: =IF(OR(ISERROR(VLOOKUP(C13, Resultados_Reales!$A$4:$I$107, 5, FALSE)), ISERROR(VLOOKUP(C13, Resultados_Reales!$A$4:$I$107, 6, FALSE)), VLOOKUP(C13, Resultados_Reales!$A$4:$I$107, 5, FALSE)="", VLOOKUP(C13, Resultados_Reales!$A$4:$I$107, 6, FALSE)=""), 0, IF(AND(VLOOKUP(C13, Resultados_Reales!$A$4:$I$107, 5, FALSE)=G13, VLOOKUP(C13, Resultados_Reales!$A$4:$I$107, 6, FALSE)=H13), Configuracion!$B$5, IF(SIGN(VLOOKUP(C13, Resultados_Reales!$A$4:$I$107, 5, FALSE)-VLOOKUP(C13, Resultados_Reales!$A$4:$I$107, 6, FALSE)) = SIGN(G13-H13), Configuracion!$B$4, 0)))
A14: =B14&"_"&C14 | K14: =IF(OR(ISERROR(VLOOKUP(C14, Resultados_Reales!$A$4:$I$107, 5, FALSE)), ISERROR(VLOOKUP(C14, Resultados_Reales!$A$4:$I$107, 6, FALSE)), VLOOKUP(C14, Resultados_Reales!$A$4:$I$107, 5, FALSE)="", VLOOKUP(C14, Resultados_Reales!$A$4:$I$107, 6, FALSE)=""), 0, IF(AND(VLOOKUP(C14, Resultados_Reales!$A$4:$I$107, 5, FALSE)=G14, VLOOKUP(C14, Resultados_Reales!$A$4:$I$107, 6, FALSE)=H14), Configuracion!$B$5, IF(SIGN(VLOOKUP(C14, Resultados_Reales!$A$4:$I$107, 5, FALSE)-VLOOKUP(C14, Resultados_Reales!$A$4:$I$107, 6, FALSE)) = SIGN(G14-H14), Configuracion!$B$4, 0)))
A15: =B15&"_"&C15 | K15: =IF(OR(ISERROR(VLOOKUP(C15, Resultados_Reales!$A$4:$I$107, 5, FALSE)), ISERROR(VLOOKUP(C15, Resultados_Reales!$A$4:$I$107, 6, FALSE)), VLOOKUP(C15, Resultados_Reales!$A$4:$I$107, 5, FALSE)="", VLOOKUP(C15, Resultados_Reales!$A$4:$I$107, 6, FALSE)=""), 0, IF(AND(VLOOKUP(C15, Resultados_Reales!$A$4:$I$107, 5, FALSE)=G15, VLOOKUP(C15, Resultados_Reales!$A$4:$I$107, 6, FALSE)=H15), Configuracion!$B$5, IF(SIGN(VLOOKUP(C15, Resultados_Reales!$A$4:$I$107, 5, FALSE)-VLOOKUP(C15, Resultados_Reales!$A$4:$I$107, 6, FALSE)) = SIGN(G15-H15), Configuracion!$B$4, 0)))
... A1999: =B1999&"_"&C1999 | K1999: =IF(OR(ISERROR(VLOOKUP(C1999, Resultados_Reales!$A$4:$I$107, 5, FALSE)), ISERROR(VLOOKUP(C1999, Resultados_Reales!$A$4:$I$107, 6, FALSE)), VLOOKUP(C1999, Resultados_Reales!$A$4:$I$107, 5, FALSE)="", VLOOKUP(C1999, Resultados_Reales!$A$4:$I$107, 6, FALSE)=""), 0, IF(AND(VLOOKUP(C1999, Resultados_Reales!$A$4:$I$107, 5, FALSE)=G1999, VLOOKUP(C1999, Resultados_Reales!$A$4:$I$107, 6, FALSE)=H1999), Configuracion!$B$5, IF(SIGN(VLOOKUP(C1999, Resultados_Reales!$A$4:$I$107, 5, FALSE)-VLOOKUP(C1999, Resultados_Reales!$A$4:$I$107, 6, FALSE)) = SIGN(G1999-H1999), Configuracion!$B$4, 0)))

Sheet Clasificacion_General
A1: CLASIFICACIÓN GENERAL DE PARTICIPANTES
A2: Nota: Puedes ordenar esta tabla seleccionándola y ordenando por la columna 'PUNTOS TOTALES' de mayor a menor.
A3: Pos | B3: Participante | C3: Puntos Partidos | D3: Puntos Balón Oro | E3: Puntos Balón Plata | F3: Puntos Balón Bronce | G3: Puntos Bota Oro | H3: Puntos Bota Plata | I3: Puntos Bota Bronce | J3: PUNTOS TOTALES
A4: =IF(B4="","",RANK(J4, $J$4:$J$33)) | C4: =IF(B4="","",SUMIFS(Predicciones_Master!$K$4:$K$2000, Predicciones_Master!$B$4:$B$2000, B4)) | D4: =IF(B4="","",IFERROR(IF(AND(Configuracion!$B$17<>"", VLOOKUP(B4, Predicciones_Master!$B$4:$Q$2000, 11, FALSE)=Configuracion!$B$17), Configuracion!$B$6, 0), 0)) | E4: =IF(B4="","",IFERROR(IF(AND(Configuracion!$B$18<>"", VLOOKUP(B4, Predicciones_Master!$B$4:$Q$2000, 12, FALSE)=Configuracion!$B$18), Configuracion!$B$7, 0), 0)) | F4: =IF(B4="","",IFERROR(IF(AND(Configuracion!$B$19<>"", VLOOKUP(B4, Predicciones_Master!$B$4:$Q$2000, 13, FALSE)=Configuracion!$B$19), Configuracion!$B$8, 0), 0)) | G4: =IF(B4="","",IFERROR(IF(AND(Configuracion!$B$20<>"", VLOOKUP(B4, Predicciones_Master!$B$4:$Q$2000, 14, FALSE)=Configuracion!$B$20), Configuracion!$B$9, 0), 0)) | H4: =IF(B4="","",IFERROR(IF(AND(Configuracion!$B$21<>"", VLOOKUP(B4, Predicciones_Master!$B$4:$Q$2000, 15, FALSE)=Configuracion!$B$21), Configuracion!$B$10, 0), 0)) | I4: =IF(B4="","",IFERROR(IF(AND(Configuracion!$B$22<>"", VLOOKUP(B4, Predicciones_Master!$B$4:$Q$2000, 16, FALSE)=Configuracion!$B$22), Configuracion!$B$11, 0), 0)) | J4: =IF(B4="","",SUM(C4:I4))
A5: =IF(B5="","",RANK(J5, $J$4:$J$33)) | C5: =IF(B5="","",SUMIFS(Predicciones_Master!$K$4:$K$2000, Predicciones_Master!$B$4:$B$2000, B5)) | D5: =IF(B5="","",IFERROR(IF(AND(Configuracion!$B$17<>"", VLOOKUP(B5, Predicciones_Master!$B$4:$Q$2000, 11, FALSE)=Configuracion!$B$17), Configuracion!$B$6, 0), 0)) | E5: =IF(B5="","",IFERROR(IF(AND(Configuracion!$B$18<>"", VLOOKUP(B5, Predicciones_Master!$B$4:$Q$2000, 12, FALSE)=Configuracion!$B$18), Configuracion!$B$7, 0), 0)) | F5: =IF(B5="","",IFERROR(IF(AND(Configuracion!$B$19<>"", VLOOKUP(B5, Predicciones_Master!$B$4:$Q$2000, 13, FALSE)=Configuracion!$B$19), Configuracion!$B$8, 0), 0)) | G5: =IF(B5="","",IFERROR(IF(AND(Configuracion!$B$20<>"", VLOOKUP(B5, Predicciones_Master!$B$4:$Q$2000, 14, FALSE)=Configuracion!$B$20), Configuracion!$B$9, 0), 0)) | H5: =IF(B5="","",IFERROR(IF(AND(Configuracion!$B$21<>"", VLOOKUP(B5, Predicciones_Master!$B$4:$Q$2000, 15, FALSE)=Configuracion!$B$21), Configuracion!$B$10, 0), 0)) | I5: =IF(B5="","",IFERROR(IF(AND(Configuracion!$B$22<>"", VLOOKUP(B5, Predicciones_Master!$B$4:$Q$2000, 16, FALSE)=Configuracion!$B$22), Configuracion!$B$11, 0), 0)) | J5: =IF(B5="","",SUM(C5:I5))
A6: =IF(B6="","",RANK(J6, $J$4:$J$33)) | C6: =IF(B6="","",SUMIFS(Predicciones_Master!$K$4:$K$2000, Predicciones_Master!$B$4:$B$2000, B6)) | D6: =IF(B6="","",IFERROR(IF(AND(Configuracion!$B$17<>"", VLOOKUP(B6, Predicciones_Master!$B$4:$Q$2000, 11, FALSE)=Configuracion!$B$17), Configuracion!$B$6, 0), 0)) | E6: =IF(B6="","",IFERROR(IF(AND(Configuracion!$B$18<>"", VLOOKUP(B6, Predicciones_Master!$B$4:$Q$2000, 12, FALSE)=Configuracion!$B$18), Configuracion!$B$7, 0), 0)) | F6: =IF(B6="","",IFERROR(IF(AND(Configuracion!$B$19<>"", VLOOKUP(B6, Predicciones_Master!$B$4:$Q$2000, 13, FALSE)=Configuracion!$B$19), Configuracion!$B$8, 0), 0)) | G6: =IF(B6="","",IFERROR(IF(AND(Configuracion!$B$20<>"", VLOOKUP(B6, Predicciones_Master!$B$4:$Q$2000, 14, FALSE)=Configuracion!$B$20), Configuracion!$B$9, 0), 0)) | H6: =IF(B6="","",IFERROR(IF(AND(Configuracion!$B$21<>"", VLOOKUP(B6, Predicciones_Master!$B$4:$Q$2000, 15, FALSE)=Configuracion!$B$21), Configuracion!$B$10, 0), 0)) | I6: =IF(B6="","",IFERROR(IF(AND(Configuracion!$B$22<>"", VLOOKUP(B6, Predicciones_Master!$B$4:$Q$2000, 16, FALSE)=Configuracion!$B$22), Configuracion!$B$11, 0), 0)) | J6: =IF(B6="","",SUM(C6:I6))
A7: =IF(B7="","",RANK(J7, $J$4:$J$33)) | C7: =IF(B7="","",SUMIFS(Predicciones_Master!$K$4:$K$2000, Predicciones_Master!$B$4:$B$2000, B7)) | D7: =IF(B7="","",IFERROR(IF(AND(Configuracion!$B$17<>"", VLOOKUP(B7, Predicciones_Master!$B$4:$Q$2000, 11, FALSE)=Configuracion!$B$17), Configuracion!$B$6, 0), 0)) | E7: =IF(B7="","",IFERROR(IF(AND(Configuracion!$B$18<>"", VLOOKUP(B7, Predicciones_Master!$B$4:$Q$2000, 12, FALSE)=Configuracion!$B$18), Configuracion!$B$7, 0), 0)) | F7: =IF(B7="","",IFERROR(IF(AND(Configuracion!$B$19<>"", VLOOKUP(B7, Predicciones_Master!$B$4:$Q$2000, 13, FALSE)=Configuracion!$B$19), Configuracion!$B$8, 0), 0)) | G7: =IF(B7="","",IFERROR(IF(AND(Configuracion!$B$20<>"", VLOOKUP(B7, Predicciones_Master!$B$4:$Q$2000, 14, FALSE)=Configuracion!$B$20), Configuracion!$B$9, 0), 0)) | H7: =IF(B7="","",IFERROR(IF(AND(Configuracion!$B$21<>"", VLOOKUP(B7, Predicciones_Master!$B$4:$Q$2000, 15, FALSE)=Configuracion!$B$21), Configuracion!$B$10, 0), 0)) | I7: =IF(B7="","",IFERROR(IF(AND(Configuracion!$B$22<>"", VLOOKUP(B7, Predicciones_Master!$B$4:$Q$2000, 16, FALSE)=Configuracion!$B$22), Configuracion!$B$11, 0), 0)) | J7: =IF(B7="","",SUM(C7:I7))
A8: =IF(B8="","",RANK(J8, $J$4:$J$33)) | C8: =IF(B8="","",SUMIFS(Predicciones_Master!$K$4:$K$2000, Predicciones_Master!$B$4:$B$2000, B8)) | D8: =IF(B8="","",IFERROR(IF(AND(Configuracion!$B$17<>"", VLOOKUP(B8, Predicciones_Master!$B$4:$Q$2000, 11, FALSE)=Configuracion!$B$17), Configuracion!$B$6, 0), 0)) | E8: =IF(B8="","",IFERROR(IF(AND(Configuracion!$B$18<>"", VLOOKUP(B8, Predicciones_Master!$B$4:$Q$2000, 12, FALSE)=Configuracion!$B$18), Configuracion!$B$7, 0), 0)) | F8: =IF(B8="","",IFERROR(IF(AND(Configuracion!$B$19<>"", VLOOKUP(B8, Predicciones_Master!$B$4:$Q$2000, 13, FALSE)=Configuracion!$B$19), Configuracion!$B$8, 0), 0)) | G8: =IF(B8="","",IFERROR(IF(AND(Configuracion!$B$20<>"", VLOOKUP(B8, Predicciones_Master!$B$4:$Q$2000, 14, FALSE)=Configuracion!$B$20), Configuracion!$B$9, 0), 0)) | H8: =IF(B8="","",IFERROR(IF(AND(Configuracion!$B$21<>"", VLOOKUP(B8, Predicciones_Master!$B$4:$Q$2000, 15, FALSE)=Configuracion!$B$21), Configuracion!$B$10, 0), 0)) | I8: =IF(B8="","",IFERROR(IF(AND(Configuracion!$B$22<>"", VLOOKUP(B8, Predicciones_Master!$B$4:$Q$2000, 16, FALSE)=Configuracion!$B$22), Configuracion!$B$11, 0), 0)) | J8: =IF(B8="","",SUM(C8:I8))
A9: =IF(B9="","",RANK(J9, $J$4:$J$33)) | C9: =IF(B9="","",SUMIFS(Predicciones_Master!$K$4:$K$2000, Predicciones_Master!$B$4:$B$2000, B9)) | D9: =IF(B9="","",IFERROR(IF(AND(Configuracion!$B$17<>"", VLOOKUP(B9, Predicciones_Master!$B$4:$Q$2000, 11, FALSE)=Configuracion!$B$17), Configuracion!$B$6, 0), 0)) | E9: =IF(B9="","",IFERROR(IF(AND(Configuracion!$B$18<>"", VLOOKUP(B9, Predicciones_Master!$B$4:$Q$2000, 12, FALSE)=Configuracion!$B$18), Configuracion!$B$7, 0), 0)) | F9: =IF(B9="","",IFERROR(IF(AND(Configuracion!$B$19<>"", VLOOKUP(B9, Predicciones_Master!$B$4:$Q$2000, 13, FALSE)=Configuracion!$B$19), Configuracion!$B$8, 0), 0)) | G9: =IF(B9="","",IFERROR(IF(AND(Configuracion!$B$20<>"", VLOOKUP(B9, Predicciones_Master!$B$4:$Q$2000, 14, FALSE)=Configuracion!$B$20), Configuracion!$B$9, 0), 0)) | H9: =IF(B9="","",IFERROR(IF(AND(Configuracion!$B$21<>"", VLOOKUP(B9, Predicciones_Master!$B$4:$Q$2000, 15, FALSE)=Configuracion!$B$21), Configuracion!$B$10, 0), 0)) | I9: =IF(B9="","",IFERROR(IF(AND(Configuracion!$B$22<>"", VLOOKUP(B9, Predicciones_Master!$B$4:$Q$2000, 16, FALSE)=Configuracion!$B$22), Configuracion!$B$11, 0), 0)) | J9: =IF(B9="","",SUM(C9:I9))
A10: =IF(B10="","",RANK(J10, $J$4:$J$33)) | C10: =IF(B10="","",SUMIFS(Predicciones_Master!$K$4:$K$2000, Predicciones_Master!$B$4:$B$2000, B10)) | D10: =IF(B10="","",IFERROR(IF(AND(Configuracion!$B$17<>"", VLOOKUP(B10, Predicciones_Master!$B$4:$Q$2000, 11, FALSE)=Configuracion!$B$17), Configuracion!$B$6, 0), 0)) | E10: =IF(B10="","",IFERROR(IF(AND(Configuracion!$B$18<>"", VLOOKUP(B10, Predicciones_Master!$B$4:$Q$2000, 12, FALSE)=Configuracion!$B$18), Configuracion!$B$7, 0), 0)) | F10: =IF(B10="","",IFERROR(IF(AND(Configuracion!$B$19<>"", VLOOKUP(B10, Predicciones_Master!$B$4:$Q$2000, 13, FALSE)=Configuracion!$B$19), Configuracion!$B$8, 0), 0)) | G10: =IF(B10="","",IFERROR(IF(AND(Configuracion!$B$20<>"", VLOOKUP(B10, Predicciones_Master!$B$4:$Q$2000, 14, FALSE)=Configuracion!$B$20), Configuracion!$B$9, 0), 0)) | H10: =IF(B10="","",IFERROR(IF(AND(Configuracion!$B$21<>"", VLOOKUP(B10, Predicciones_Master!$B$4:$Q$2000, 15, FALSE)=Configuracion!$B$21), Configuracion!$B$10, 0), 0)) | I10: =IF(B10="","",IFERROR(IF(AND(Configuracion!$B$22<>"", VLOOKUP(B10, Predicciones_Master!$B$4:$Q$2000, 16, FALSE)=Configuracion!$B$22), Configuracion!$B$11, 0), 0)) | J10: =IF(B10="","",SUM(C10:I10))
A11: =IF(B11="","",RANK(J11, $J$4:$J$33)) | C11: =IF(B11="","",SUMIFS(Predicciones_Master!$K$4:$K$2000, Predicciones_Master!$B$4:$B$2000, B11)) | D11: =IF(B11="","",IFERROR(IF(AND(Configuracion!$B$17<>"", VLOOKUP(B11, Predicciones_Master!$B$4:$Q$2000, 11, FALSE)=Configuracion!$B$17), Configuracion!$B$6, 0), 0)) | E11: =IF(B11="","",IFERROR(IF(AND(Configuracion!$B$18<>"", VLOOKUP(B11, Predicciones_Master!$B$4:$Q$2000, 12, FALSE)=Configuracion!$B$18), Configuracion!$B$7, 0), 0)) | F11: =IF(B11="","",IFERROR(IF(AND(Configuracion!$B$19<>"", VLOOKUP(B11, Predicciones_Master!$B$4:$Q$2000, 13, FALSE)=Configuracion!$B$19), Configuracion!$B$8, 0), 0)) | G11: =IF(B11="","",IFERROR(IF(AND(Configuracion!$B$20<>"", VLOOKUP(B11, Predicciones_Master!$B$4:$Q$2000, 14, FALSE)=Configuracion!$B$20), Configuracion!$B$9, 0), 0)) | H11: =IF(B11="","",IFERROR(IF(AND(Configuracion!$B$21<>"", VLOOKUP(B11, Predicciones_Master!$B$4:$Q$2000, 15, FALSE)=Configuracion!$B$21), Configuracion!$B$10, 0), 0)) | I11: =IF(B11="","",IFERROR(IF(AND(Configuracion!$B$22<>"", VLOOKUP(B11, Predicciones_Master!$B$4:$Q$2000, 16, FALSE)=Configuracion!$B$22), Configuracion!$B$11, 0), 0)) | J11: =IF(B11="","",SUM(C11:I11))
A12: =IF(B12="","",RANK(J12, $J$4:$J$33)) | C12: =IF(B12="","",SUMIFS(Predicciones_Master!$K$4:$K$2000, Predicciones_Master!$B$4:$B$2000, B12)) | D12: =IF(B12="","",IFERROR(IF(AND(Configuracion!$B$17<>"", VLOOKUP(B12, Predicciones_Master!$B$4:$Q$2000, 11, FALSE)=Configuracion!$B$17), Configuracion!$B$6, 0), 0)) | E12: =IF(B12="","",IFERROR(IF(AND(Configuracion!$B$18<>"", VLOOKUP(B12, Predicciones_Master!$B$4:$Q$2000, 12, FALSE)=Configuracion!$B$18), Configuracion!$B$7, 0), 0)) | F12: =IF(B12="","",IFERROR(IF(AND(Configuracion!$B$19<>"", VLOOKUP(B12, Predicciones_Master!$B$4:$Q$2000, 13, FALSE)=Configuracion!$B$19), Configuracion!$B$8, 0), 0)) | G12: =IF(B12="","",IFERROR(IF(AND(Configuracion!$B$20<>"", VLOOKUP(B12, Predicciones_Master!$B$4:$Q$2000, 14, FALSE)=Configuracion!$B$20), Configuracion!$B$9, 0), 0)) | H12: =IF(B12="","",IFERROR(IF(AND(Configuracion!$B$21<>"", VLOOKUP(B12, Predicciones_Master!$B$4:$Q$2000, 15, FALSE)=Configuracion!$B$21), Configuracion!$B$10, 0), 0)) | I12: =IF(B12="","",IFERROR(IF(AND(Configuracion!$B$22<>"", VLOOKUP(B12, Predicciones_Master!$B$4:$Q$2000, 16, FALSE)=Configuracion!$B$22), Configuracion!$B$11, 0), 0)) | J12: =IF(B12="","",SUM(C12:I12))
A13: =IF(B13="","",RANK(J13, $J$4:$J$33)) | C13: =IF(B13="","",SUMIFS(Predicciones_Master!$K$4:$K$2000, Predicciones_Master!$B$4:$B$2000, B13)) | D13: =IF(B13="","",IFERROR(IF(AND(Configuracion!$B$17<>"", VLOOKUP(B13, Predicciones_Master!$B$4:$Q$2000, 11, FALSE)=Configuracion!$B$17), Configuracion!$B$6, 0), 0)) | E13: =IF(B13="","",IFERROR(IF(AND(Configuracion!$B$18<>"", VLOOKUP(B13, Predicciones_Master!$B$4:$Q$2000, 12, FALSE)=Configuracion!$B$18), Configuracion!$B$7, 0), 0)) | F13: =IF(B13="","",IFERROR(IF(AND(Configuracion!$B$19<>"", VLOOKUP(B13, Predicciones_Master!$B$4:$Q$2000, 13, FALSE)=Configuracion!$B$19), Configuracion!$B$8, 0), 0)) | G13: =IF(B13="","",IFERROR(IF(AND(Configuracion!$B$20<>"", VLOOKUP(B13, Predicciones_Master!$B$4:$Q$2000, 14, FALSE)=Configuracion!$B$20), Configuracion!$B$9, 0), 0)) | H13: =IF(B13="","",IFERROR(IF(AND(Configuracion!$B$21<>"", VLOOKUP(B13, Predicciones_Master!$B$4:$Q$2000, 15, FALSE)=Configuracion!$B$21), Configuracion!$B$10, 0), 0)) | I13: =IF(B13="","",IFERROR(IF(AND(Configuracion!$B$22<>"", VLOOKUP(B13, Predicciones_Master!$B$4:$Q$2000, 16, FALSE)=Configuracion!$B$22), Configuracion!$B$11, 0), 0)) | J13: =IF(B13="","",SUM(C13:I13))
A14: =IF(B14="","",RANK(J14, $J$4:$J$33)) | C14: =IF(B14="","",SUMIFS(Predicciones_Master!$K$4:$K$2000, Predicciones_Master!$B$4:$B$2000, B14)) | D14: =IF(B14="","",IFERROR(IF(AND(Configuracion!$B$17<>"", VLOOKUP(B14, Predicciones_Master!$B$4:$Q$2000, 11, FALSE)=Configuracion!$B$17), Configuracion!$B$6, 0), 0)) | E14: =IF(B14="","",IFERROR(IF(AND(Configuracion!$B$18<>"", VLOOKUP(B14, Predicciones_Master!$B$4:$Q$2000, 12, FALSE)=Configuracion!$B$18), Configuracion!$B$7, 0), 0)) | F14: =IF(B14="","",IFERROR(IF(AND(Configuracion!$B$19<>"", VLOOKUP(B14, Predicciones_Master!$B$4:$Q$2000, 13, FALSE)=Configuracion!$B$19), Configuracion!$B$8, 0), 0)) | G14: =IF(B14="","",IFERROR(IF(AND(Configuracion!$B$20<>"", VLOOKUP(B14, Predicciones_Master!$B$4:$Q$2000, 14, FALSE)=Configuracion!$B$20), Configuracion!$B$9, 0), 0)) | H14: =IF(B14="","",IFERROR(IF(AND(Configuracion!$B$21<>"", VLOOKUP(B14, Predicciones_Master!$B$4:$Q$2000, 15, FALSE)=Configuracion!$B$21), Configuracion!$B$10, 0), 0)) | I14: =IF(B14="","",IFERROR(IF(AND(Configuracion!$B$22<>"", VLOOKUP(B14, Predicciones_Master!$B$4:$Q$2000, 16, FALSE)=Configuracion!$B$22), Configuracion!$B$11, 0), 0)) | J14: =IF(B14="","",SUM(C14:I14))
A15: =IF(B15="","",RANK(J15, $J$4:$J$33)) | C15: =IF(B15="","",SUMIFS(Predicciones_Master!$K$4:$K$2000, Predicciones_Master!$B$4:$B$2000, B15)) | D15: =IF(B15="","",IFERROR(IF(AND(Configuracion!$B$17<>"", VLOOKUP(B15, Predicciones_Master!$B$4:$Q$2000, 11, FALSE)=Configuracion!$B$17), Configuracion!$B$6, 0), 0)) | E15: =IF(B15="","",IFERROR(IF(AND(Configuracion!$B$18<>"", VLOOKUP(B15, Predicciones_Master!$B$4:$Q$2000, 12, FALSE)=Configuracion!$B$18), Configuracion!$B$7, 0), 0)) | F15: =IF(B15="","",IFERROR(IF(AND(Configuracion!$B$19<>"", VLOOKUP(B15, Predicciones_Master!$B$4:$Q$2000, 13, FALSE)=Configuracion!$B$19), Configuracion!$B$8, 0), 0)) | G15: =IF(B15="","",IFERROR(IF(AND(Configuracion!$B$20<>"", VLOOKUP(B15, Predicciones_Master!$B$4:$Q$2000, 14, FALSE)=Configuracion!$B$20), Configuracion!$B$9, 0), 0)) | H15: =IF(B15="","",IFERROR(IF(AND(Configuracion!$B$21<>"", VLOOKUP(B15, Predicciones_Master!$B$4:$Q$2000, 15, FALSE)=Configuracion!$B$21), Configuracion!$B$10, 0), 0)) | I15: =IF(B15="","",IFERROR(IF(AND(Configuracion!$B$22<>"", VLOOKUP(B15, Predicciones_Master!$B$4:$Q$2000, 16, FALSE)=Configuracion!$B$22), Configuracion!$B$11, 0), 0)) | J15: =IF(B15="","",SUM(C15:I15))
... A33: =IF(B33="","",RANK(J33, $J$4:$J$33)) | C33: =IF(B33="","",SUMIFS(Predicciones_Master!$K$4:$K$2000, Predicciones_Master!$B$4:$B$2000, B33)) | D33: =IF(B33="","",IFERROR(IF(AND(Configuracion!$B$17<>"", VLOOKUP(B33, Predicciones_Master!$B$4:$Q$2000, 11, FALSE)=Configuracion!$B$17), Configuracion!$B$6, 0), 0)) | E33: =IF(B33="","",IFERROR(IF(AND(Configuracion!$B$18<>"", VLOOKUP(B33, Predicciones_Master!$B$4:$Q$2000, 12, FALSE)=Configuracion!$B$18), Configuracion!$B$7, 0), 0)) | F33: =IF(B33="","",IFERROR(IF(AND(Configuracion!$B$19<>"", VLOOKUP(B33, Predicciones_Master!$B$4:$Q$2000, 13, FALSE)=Configuracion!$B$19), Configuracion!$B$8, 0), 0)) | G33: =IF(B33="","",IFERROR(IF(AND(Configuracion!$B$20<>"", VLOOKUP(B33, Predicciones_Master!$B$4:$Q$2000, 14, FALSE)=Configuracion!$B$20), Configuracion!$B$9, 0), 0)) | H33: =IF(B33="","",IFERROR(IF(AND(Configuracion!$B$21<>"", VLOOKUP(B33, Predicciones_Master!$B$4:$Q$2000, 15, FALSE)=Configuracion!$B$21), Configuracion!$B$10, 0), 0)) | I33: =IF(B33="","",IFERROR(IF(AND(Configuracion!$B$22<>"", VLOOKUP(B33, Predicciones_Master!$B$4:$Q$2000, 16, FALSE)=Configuracion!$B$22), Configuracion!$B$11, 0), 0)) | J33: =IF(B33="","",SUM(C33:I33))

Sheet Seguimiento_Partidos
A1: MATRIZ DE SEGUIMIENTO Y ACUMULADO POR PARTIDO | E1: Participante 1 | G1: Participante 2 | I1: Participante 3 | K1: Participante 4 | M1: Participante 5 | O1: Participante 6 | Q1: Participante 7 | S1: Participante 8 | U1: Participante 9 | W1: Participante 10
A2: ID Partido | B2: Fase | C2: Partido (Local vs Visitante) | D2: Resultado Real | E2: Pronóstico | F2: Puntos | G2: Pronóstico | H2: Puntos | I2: Pronóstico | J2: Puntos | K2: Pronóstico | L2: Puntos | M2: Pronóstico | N2: Puntos | O2: Pronóstico | P2: Puntos | Q2: Pronóstico | R2: Puntos | S2: Pronóstico | T2: Puntos | U2: Pronóstico | V2: Puntos | W2: Pronóstico | X2: Puntos
A4: =Resultados_Reales!A4 | B4: =Resultados_Reales!B4 | C4: =Resultados_Reales!C4 & " vs " & Resultados_Reales!D4 | D4: =IF(OR(Resultados_Reales!E4="", Resultados_Reales!F4=""), "Por Jugar", Resultados_Reales!E4 & " - " & Resultados_Reales!F4) | E4: =IFERROR(VLOOKUP(E$1&"_"&$A4, Predicciones_Master!$A$4:$Q$2000, 7, FALSE) & " - " & VLOOKUP(E$1&"_"&$A4, Predicciones_Master!$A$4:$Q$2000, 8, FALSE), "N/A") | F4: =IF($D4="Por Jugar", "", IFERROR(VLOOKUP(E$1&"_"&$A4, Predicciones_Master!$A$4:$Q$2000, 11, FALSE), 0)) | G4: =IFERROR(VLOOKUP(G$1&"_"&$A4, Predicciones_Master!$A$4:$Q$2000, 7, FALSE) & " - " & VLOOKUP(G$1&"_"&$A4, Predicciones_Master!$A$4:$Q$2000, 8, FALSE), "N/A") | H4: =IF($D4="Por Jugar", "", IFERROR(VLOOKUP(G$1&"_"&$A4, Predicciones_Master!$A$4:$Q$2000, 11, FALSE), 0)) | I4: =IFERROR(VLOOKUP(I$1&"_"&$A4, Predicciones_Master!$A$4:$Q$2000, 7, FALSE) & " - " & VLOOKUP(I$1&"_"&$A4, Predicciones_Master!$A$4:$Q$2000, 8, FALSE), "N/A") | J4: =IF($D4="Por Jugar", "", IFERROR(VLOOKUP(I$1&"_"&$A4, Predicciones_Master!$A$4:$Q$2000, 11, FALSE), 0)) | K4: =IFERROR(VLOOKUP(K$1&"_"&$A4, Predicciones_Master!$A$4:$Q$2000, 7, FALSE) & " - " & VLOOKUP(K$1&"_"&$A4, Predicciones_Master!$A$4:$Q$2000, 8, FALSE), "N/A") | L4: =IF($D4="Por Jugar", "", IFERROR(VLOOKUP(K$1&"_"&$A4, Predicciones_Master!$A$4:$Q$2000, 11, FALSE), 0)) | M4: =IFERROR(VLOOKUP(M$1&"_"&$A4, Predicciones_Master!$A$4:$Q$2000, 7, FALSE) & " - " & VLOOKUP(M$1&"_"&$A4, Predicciones_Master!$A$4:$Q$2000, 8, FALSE), "N/A") | N4: =IF($D4="Por Jugar", "", IFERROR(VLOOKUP(M$1&"_"&$A4, Predicciones_Master!$A$4:$Q$2000, 11, FALSE), 0)) | O4: =IFERROR(VLOOKUP(O$1&"_"&$A4, Predicciones_Master!$A$4:$Q$2000, 7, FALSE) & " - " & VLOOKUP(O$1&"_"&$A4, Predicciones_Master!$A$4:$Q$2000, 8, FALSE), "N/A") | P4: =IF($D4="Por Jugar", "", IFERROR(VLOOKUP(O$1&"_"&$A4, Predicciones_Master!$A$4:$Q$2000, 11, FALSE), 0)) | Q4: =IFERROR(VLOOKUP(Q$1&"_"&$A4, Predicciones_Master!$A$4:$Q$2000, 7, FALSE) & " - " & VLOOKUP(Q$1&"_"&$A4, Predicciones_Master!$A$4:$Q$2000, 8, FALSE), "N/A") | R4: =IF($D4="Por Jugar", "", IFERROR(VLOOKUP(Q$1&"_"&$A4, Predicciones_Master!$A$4:$Q$2000, 11, FALSE), 0)) | S4: =IFERROR(VLOOKUP(S$1&"_"&$A4, Predicciones_Master!$A$4:$Q$2000, 7, FALSE) & " - " & VLOOKUP(S$1&"_"&$A4, Predicciones_Master!$A$4:$Q$2000, 8, FALSE), "N/A") | T4: =IF($D4="Por Jugar", "", IFERROR(VLOOKUP(S$1&"_"&$A4, Predicciones_Master!$A$4:$Q$2000, 11, FALSE), 0)) | U4: =IFERROR(VLOOKUP(U$1&"_"&$A4, Predicciones_Master!$A$4:$Q$2000, 7, FALSE) & " - " & VLOOKUP(U$1&"_"&$A4, Predicciones_Master!$A$4:$Q$2000, 8, FALSE), "N/A") | V4: =IF($D4="Por Jugar", "", IFERROR(VLOOKUP(U$1&"_"&$A4, Predicciones_Master!$A$4:$Q$2000, 11, FALSE), 0)) | W4: =IFERROR(VLOOKUP(W$1&"_"&$A4, Predicciones_Master!$A$4:$Q$2000, 7, FALSE) & " - " & VLOOKUP(W$1&"_"&$A4, Predicciones_Master!$A$4:$Q$2000, 8, FALSE), "N/A") | X4: =IF($D4="Por Jugar", "", IFERROR(VLOOKUP(W$1&"_"&$A4, Predicciones_Master!$A$4:$Q$2000, 11, FALSE), 0))
A5: =Resultados_Reales!A5 | B5: =Resultados_Reales!B5 | C5: =Resultados_Reales!C5 & " vs " & Resultados_Reales!D5 | D5: =IF(OR(Resultados_Reales!E5="", Resultados_Reales!F5=""), "Por Jugar", Resultados_Reales!E5 & " - " & Resultados_Reales!F5) | E5: =IFERROR(VLOOKUP(E$1&"_"&$A5, Predicciones_Master!$A$4:$Q$2000, 7, FALSE) & " - " & VLOOKUP(E$1&"_"&$A5, Predicciones_Master!$A$4:$Q$2000, 8, FALSE), "N/A") | F5: =IF($D5="Por Jugar", "", IFERROR(VLOOKUP(E$1&"_"&$A5, Predicciones_Master!$A$4:$Q$2000, 11, FALSE), 0)) | G5: =IFERROR(VLOOKUP(G$1&"_"&$A5, Predicciones_Master!$A$4:$Q$2000, 7, FALSE) & " - " & VLOOKUP(G$1&"_"&$A5, Predicciones_Master!$A$4:$Q$2000, 8, FALSE), "N/A") | H5: =IF($D5="Por Jugar", "", IFERROR(VLOOKUP(G$1&"_"&$A5, Predicciones_Master!$A$4:$Q$2000, 11, FALSE), 0)) | I5: =IFERROR(VLOOKUP(I$1&"_"&$A5, Predicciones_Master!$A$4:$Q$2000, 7, FALSE) & " - " & VLOOKUP(I$1&"_"&$A5, Predicciones_Master!$A$4:$Q$2000, 8, FALSE), "N/A") | J5: =IF($D5="Por Jugar", "", IFERROR(VLOOKUP(I$1&"_"&$A5, Predicciones_Master!$A$4:$Q$2000, 11, FALSE), 0)) | K5: =IFERROR(VLOOKUP(K$1&"_"&$A5, Predicciones_Master!$A$4:$Q$2000, 7, FALSE) & " - " & VLOOKUP(K$1&"_"&$A5, Predicciones_Master!$A$4:$Q$2000, 8, FALSE), "N/A") | L5: =IF($D5="Por Jugar", "", IFERROR(VLOOKUP(K$1&"_"&$A5, Predicciones_Master!$A$4:$Q$2000, 11, FALSE), 0)) | M5: =IFERROR(VLOOKUP(M$1&"_"&$A5, Predicciones_Master!$A$4:$Q$2000, 7, FALSE) & " - " & VLOOKUP(M$1&"_"&$A5, Predicciones_Master!$A$4:$Q$2000, 8, FALSE), "N/A") | N5: =IF($D5="Por Jugar", "", IFERROR(VLOOKUP(M$1&"_"&$A5, Predicciones_Master!$A$4:$Q$2000, 11, FALSE), 0)) | O5: =IFERROR(VLOOKUP(O$1&"_"&$A5, Predicciones_Master!$A$4:$Q$2000, 7, FALSE) & " - " & VLOOKUP(O$1&"_"&$A5, Predicciones_Master!$A$4:$Q$2000, 8, FALSE), "N/A") | P5: =IF($D5="Por Jugar", "", IFERROR(VLOOKUP(O$1&"_"&$A5, Predicciones_Master!$A$4:$Q$2000, 11, FALSE), 0)) | Q5: =IFERROR(VLOOKUP(Q$1&"_"&$A5, Predicciones_Master!$A$4:$Q$2000, 7, FALSE) & " - " & VLOOKUP(Q$1&"_"&$A5, Predicciones_Master!$A$4:$Q$2000, 8, FALSE), "N/A") | R5: =IF($D5="Por Jugar", "", IFERROR(VLOOKUP(Q$1&"_"&$A5, Predicciones_Master!$A$4:$Q$2000, 11, FALSE), 0)) | S5: =IFERROR(VLOOKUP(S$1&"_"&$A5, Predicciones_Master!$A$4:$Q$2000, 7, FALSE) & " - " & VLOOKUP(S$1&"_"&$A5, Predicciones_Master!$A$4:$Q$2000, 8, FALSE), "N/A") | T5: =IF($D5="Por Jugar", "", IFERROR(VLOOKUP(S$1&"_"&$A5, Predicciones_Master!$A$4:$Q$2000, 11, FALSE), 0)) | U5: =IFERROR(VLOOKUP(U$1&"_"&$A5, Predicciones_Master!$A$4:$Q$2000, 7, FALSE) & " - " & VLOOKUP(U$1&"_"&$A5, Predicciones_Master!$A$4:$Q$2000, 8, FALSE), "N/A") | V5: =IF($D5="Por Jugar", "", IFERROR(VLOOKUP(U$1&"_"&$A5, Predicciones_Master!$A$4:$Q$2000, 11, FALSE), 0)) | W5: =IFERROR(VLOOKUP(W$1&"_"&$A5, Predicciones_Master!$A$4:$Q$2000, 7, FALSE) & " - " & VLOOKUP(W$1&"_"&$A5, Predicciones_Master!$A$4:$Q$2000, 8, FALSE), "N/A") | X5: =IF($D5="Por Jugar", "", IFERROR(VLOOKUP(W$1&"_"&$A5, Predicciones_Master!$A$4:$Q$2000, 11, FALSE), 0))
A6: =Resultados_Reales!A6 | B6: =Resultados_Reales!B6 | C6: =Resultados_Reales!C6 & " vs " & Resultados_Reales!D6 | D6: =IF(OR(Resultados_Reales!E6="", Resultados_Reales!F6=""), "Por Jugar", Resultados_Reales!E6 & " - " & Resultados_Reales!F6) | E6: =IFERROR(VLOOKUP(E$1&"_"&$A6, Predicciones_Master!$A$4:$Q$2000, 7, FALSE) & " - " & VLOOKUP(E$1&"_"&$A6, Predicciones_Master!$A$4:$Q$2000, 8, FALSE), "N/A") | F6: =IF($D6="Por Jugar", "", IFERROR(VLOOKUP(E$1&"_"&$A6, Predicciones_Master!$A$4:$Q$2000, 11, FALSE), 0)) | G6: =IFERROR(VLOOKUP(G$1&"_"&$A6, Predicciones_Master!$A$4:$Q$2000, 7, FALSE) & " - " & VLOOKUP(G$1&"_"&$A6, Predicciones_Master!$A$4:$Q$2000, 8, FALSE), "N/A") | H6: =IF($D6="Por Jugar", "", IFERROR(VLOOKUP(G$1&"_"&$A6, Predicciones_Master!$A$4:$Q$2000, 11, FALSE), 0)) | I6: =IFERROR(VLOOKUP(I$1&"_"&$A6, Predicciones_Master!$A$4:$Q$2000, 7, FALSE) & " - " & VLOOKUP(I$1&"_"&$A6, Predicciones_Master!$A$4:$Q$2000, 8, FALSE), "N/A") | J6: =IF($D6="Por Jugar", "", IFERROR(VLOOKUP(I$1&"_"&$A6, Predicciones_Master!$A$4:$Q$2000, 11, FALSE), 0)) | K6: =IFERROR(VLOOKUP(K$1&"_"&$A6, Predicciones_Master!$A$4:$Q$2000, 7, FALSE) & " - " & VLOOKUP(K$1&"_"&$A6, Predicciones_Master!$A$4:$Q$2000, 8, FALSE), "N/A") | L6: =IF($D6="Por Jugar", "", IFERROR(VLOOKUP(K$1&"_"&$A6, Predicciones_Master!$A$4:$Q$2000, 11, FALSE), 0)) | M6: =IFERROR(VLOOKUP(M$1&"_"&$A6, Predicciones_Master!$A$4:$Q$2000, 7, FALSE) & " - " & VLOOKUP(M$1&"_"&$A6, Predicciones_Master!$A$4:$Q$2000, 8, FALSE), "N/A") | N6: =IF($D6="Por Jugar", "", IFERROR(VLOOKUP(M$1&"_"&$A6, Predicciones_Master!$A$4:$Q$2000, 11, FALSE), 0)) | O6: =IFERROR(VLOOKUP(O$1&"_"&$A6, Predicciones_Master!$A$4:$Q$2000, 7, FALSE) & " - " & VLOOKUP(O$1&"_"&$A6, Predicciones_Master!$A$4:$Q$2000, 8, FALSE), "N/A") | P6: =IF($D6="Por Jugar", "", IFERROR(VLOOKUP(O$1&"_"&$A6, Predicciones_Master!$A$4:$Q$2000, 11, FALSE), 0)) | Q6: =IFERROR(VLOOKUP(Q$1&"_"&$A6, Predicciones_Master!$A$4:$Q$2000, 7, FALSE) & " - " & VLOOKUP(Q$1&"_"&$A6, Predicciones_Master!$A$4:$Q$2000, 8, FALSE), "N/A") | R6: =IF($D6="Por Jugar", "", IFERROR(VLOOKUP(Q$1&"_"&$A6, Predicciones_Master!$A$4:$Q$2000, 11, FALSE), 0)) | S6: =IFERROR(VLOOKUP(S$1&"_"&$A6, Predicciones_Master!$A$4:$Q$2000, 7, FALSE) & " - " & VLOOKUP(S$1&"_"&$A6, Predicciones_Master!$A$4:$Q$2000, 8, FALSE), "N/A") | T6: =IF($D6="Por Jugar", "", IFERROR(VLOOKUP(S$1&"_"&$A6, Predicciones_Master!$A$4:$Q$2000, 11, FALSE), 0)) | U6: =IFERROR(VLOOKUP(U$1&"_"&$A6, Predicciones_Master!$A$4:$Q$2000, 7, FALSE) & " - " & VLOOKUP(U$1&"_"&$A6, Predicciones_Master!$A$4:$Q$2000, 8, FALSE), "N/A") | V6: =IF($D6="Por Jugar", "", IFERROR(VLOOKUP(U$1&"_"&$A6, Predicciones_Master!$A$4:$Q$2000, 11, FALSE), 0)) | W6: =IFERROR(VLOOKUP(W$1&"_"&$A6, Predicciones_Master!$A$4:$Q$2000, 7, FALSE) & " - " & VLOOKUP(W$1&"_"&$A6, Predicciones_Master!$A$4:$Q$2000, 8, FALSE), "N/A") | X6: =IF($D6="Por Jugar", "", IFERROR(VLOOKUP(W$1&"_"&$A6, Predicciones_Master!$A$4:$Q$2000, 11, FALSE), 0))
A7: =Resultados_Reales!A7 | B7: =Resultados_Reales!B7 | C7: =Resultados_Reales!C7 & " vs " & Resultados_Reales!D7 | D7: =IF(OR(Resultados_Reales!E7="", Resultados_Reales!F7=""), "Por Jugar", Resultados_Reales!E7 & " - " & Resultados_Reales!F7) | E7: =IFERROR(VLOOKUP(E$1&"_"&$A7, Predicciones_Master!$A$4:$Q$2000, 7, FALSE) & " - " & VLOOKUP(E$1&"_"&$A7, Predicciones_Master!$A$4:$Q$2000, 8, FALSE), "N/A") | F7: =IF($D7="Por Jugar", "", IFERROR(VLOOKUP(E$1&"_"&$A7, Predicciones_Master!$A$4:$Q$2000, 11, FALSE), 0)) | G7: =IFERROR(VLOOKUP(G$1&"_"&$A7, Predicciones_Master!$A$4:$Q$2000, 7, FALSE) & " - " & VLOOKUP(G$1&"_"&$A7, Predicciones_Master!$A$4:$Q$2000, 8, FALSE), "N/A") | H7: =IF($D7="Por Jugar", "", IFERROR(VLOOKUP(G$1&"_"&$A7, Predicciones_Master!$A$4:$Q$2000, 11, FALSE), 0)) | I7: =IFERROR(VLOOKUP(I$1&"_"&$A7, Predicciones_Master!$A$4:$Q$2000, 7, FALSE) & " - " & VLOOKUP(I$1&"_"&$A7, Predicciones_Master!$A$4:$Q$2000, 8, FALSE), "N/A") | J7: =IF($D7="Por Jugar", "", IFERROR(VLOOKUP(I$1&"_"&$A7, Predicciones_Master!$A$4:$Q$2000, 11, FALSE), 0)) | K7: =IFERROR(VLOOKUP(K$1&"_"&$A7, Predicciones_Master!$A$4:$Q$2000, 7, FALSE) & " - " & VLOOKUP(K$1&"_"&$A7, Predicciones_Master!$A$4:$Q$2000, 8, FALSE), "N/A") | L7: =IF($D7="Por Jugar", "", IFERROR(VLOOKUP(K$1&"_"&$A7, Predicciones_Master!$A$4:$Q$2000, 11, FALSE), 0)) | M7: =IFERROR(VLOOKUP(M$1&"_"&$A7, Predicciones_Master!$A$4:$Q$2000, 7, FALSE) & " - " & VLOOKUP(M$1&"_"&$A7, Predicciones_Master!$A$4:$Q$2000, 8, FALSE), "N/A") | N7: =IF($D7="Por Jugar", "", IFERROR(VLOOKUP(M$1&"_"&$A7, Predicciones_Master!$A$4:$Q$2000, 11, FALSE), 0)) | O7: =IFERROR(VLOOKUP(O$1&"_"&$A7, Predicciones_Master!$A$4:$Q$2000, 7, FALSE) & " - " & VLOOKUP(O$1&"_"&$A7, Predicciones_Master!$A$4:$Q$2000, 8, FALSE), "N/A") | P7: =IF($D7="Por Jugar", "", IFERROR(VLOOKUP(O$1&"_"&$A7, Predicciones_Master!$A$4:$Q$2000, 11, FALSE), 0)) | Q7: =IFERROR(VLOOKUP(Q$1&"_"&$A7, Predicciones_Master!$A$4:$Q$2000, 7, FALSE) & " - " & VLOOKUP(Q$1&"_"&$A7, Predicciones_Master!$A$4:$Q$2000, 8, FALSE), "N/A") | R7: =IF($D7="Por Jugar", "", IFERROR(VLOOKUP(Q$1&"_"&$A7, Predicciones_Master!$A$4:$Q$2000, 11, FALSE), 0)) | S7: =IFERROR(VLOOKUP(S$1&"_"&$A7, Predicciones_Master!$A$4:$Q$2000, 7, FALSE) & " - " & VLOOKUP(S$1&"_"&$A7, Predicciones_Master!$A$4:$Q$2000, 8, FALSE), "N/A") | T7: =IF($D7="Por Jugar", "", IFERROR(VLOOKUP(S$1&"_"&$A7, Predicciones_Master!$A$4:$Q$2000, 11, FALSE), 0)) | U7: =IFERROR(VLOOKUP(U$1&"_"&$A7, Predicciones_Master!$A$4:$Q$2000, 7, FALSE) & " - " & VLOOKUP(U$1&"_"&$A7, Predicciones_Master!$A$4:$Q$2000, 8, FALSE), "N/A") | V7: =IF($D7="Por Jugar", "", IFERROR(VLOOKUP(U$1&"_"&$A7, Predicciones_Master!$A$4:$Q$2000, 11, FALSE), 0)) | W7: =IFERROR(VLOOKUP(W$1&"_"&$A7, Predicciones_Master!$A$4:$Q$2000, 7, FALSE) & " - " & VLOOKUP(W$1&"_"&$A7, Predicciones_Master!$A$4:$Q$2000, 8, FALSE), "N/A") | X7: =IF($D7="Por Jugar", "", IFERROR(VLOOKUP(W$1&"_"&$A7, Predicciones_Master!$A$4:$Q$2000, 11, FALSE), 0))
A8: =Resultados_Reales!A8 | B8: =Resultados_Reales!B8 | C8: =Resultados_Reales!C8 & " vs " & Resultados_Reales!D8 | D8: =IF(OR(Resultados_Reales!E8="", Resultados_Reales!F8=""), "Por Jugar", Resultados_Reales!E8 & " - " & Resultados_Reales!F8) | E8: =IFERROR(VLOOKUP(E$1&"_"&$A8, Predicciones_Master!$A$4:$Q$2000, 7, FALSE) & " - " & VLOOKUP(E$1&"_"&$A8, Predicciones_Master!$A$4:$Q$2000, 8, FALSE), "N/A") | F8: =IF($D8="Por Jugar", "", IFERROR(VLOOKUP(E$1&"_"&$A8, Predicciones_Master!$A$4:$Q$2000, 11, FALSE), 0)) | G8: =IFERROR(VLOOKUP(G$1&"_"&$A8, Predicciones_Master!$A$4:$Q$2000, 7, FALSE) & " - " & VLOOKUP(G$1&"_"&$A8, Predicciones_Master!$A$4:$Q$2000, 8, FALSE), "N/A") | H8: =IF($D8="Por Jugar", "", IFERROR(VLOOKUP(G$1&"_"&$A8, Predicciones_Master!$A$4:$Q$2000, 11, FALSE), 0)) | I8: =IFERROR(VLOOKUP(I$1&"_"&$A8, Predicciones_Master!$A$4:$Q$2000, 7, FALSE) & " - " & VLOOKUP(I$1&"_"&$A8, Predicciones_Master!$A$4:$Q$2000, 8, FALSE), "N/A") | J8: =IF($D8="Por Jugar", "", IFERROR(VLOOKUP(I$1&"_"&$A8, Predicciones_Master!$A$4:$Q$2000, 11, FALSE), 0)) | K8: =IFERROR(VLOOKUP(K$1&"_"&$A8, Predicciones_Master!$A$4:$Q$2000, 7, FALSE) & " - " & VLOOKUP(K$1&"_"&$A8, Predicciones_Master!$A$4:$Q$2000, 8, FALSE), "N/A") | L8: =IF($D8="Por Jugar", "", IFERROR(VLOOKUP(K$1&"_"&$A8, Predicciones_Master!$A$4:$Q$2000, 11, FALSE), 0)) | M8: =IFERROR(VLOOKUP(M$1&"_"&$A8, Predicciones_Master!$A$4:$Q$2000, 7, FALSE) & " - " & VLOOKUP(M$1&"_"&$A8, Predicciones_Master!$A$4:$Q$2000, 8, FALSE), "N/A") | N8: =IF($D8="Por Jugar", "", IFERROR(VLOOKUP(M$1&"_"&$A8, Predicciones_Master!$A$4:$Q$2000, 11, FALSE), 0)) | O8: =IFERROR(VLOOKUP(O$1&"_"&$A8, Predicciones_Master!$A$4:$Q$2000, 7, FALSE) & " - " & VLOOKUP(O$1&"_"&$A8, Predicciones_Master!$A$4:$Q$2000, 8, FALSE), "N/A") | P8: =IF($D8="Por Jugar", "", IFERROR(VLOOKUP(O$1&"_"&$A8, Predicciones_Master!$A$4:$Q$2000, 11, FALSE), 0)) | Q8: =IFERROR(VLOOKUP(Q$1&"_"&$A8, Predicciones_Master!$A$4:$Q$2000, 7, FALSE) & " - " & VLOOKUP(Q$1&"_"&$A8, Predicciones_Master!$A$4:$Q$2000, 8, FALSE), "N/A") | R8: =IF($D8="Por Jugar", "", IFERROR(VLOOKUP(Q$1&"_"&$A8, Predicciones_Master!$A$4:$Q$2000, 11, FALSE), 0)) | S8: =IFERROR(VLOOKUP(S$1&"_"&$A8, Predicciones_Master!$A$4:$Q$2000, 7, FALSE) & " - " & VLOOKUP(S$1&"_"&$A8, Predicciones_Master!$A$4:$Q$2000, 8, FALSE), "N/A") | T8: =IF($D8="Por Jugar", "", IFERROR(VLOOKUP(S$1&"_"&$A8, Predicciones_Master!$A$4:$Q$2000, 11, FALSE), 0)) | U8: =IFERROR(VLOOKUP(U$1&"_"&$A8, Predicciones_Master!$A$4:$Q$2000, 7, FALSE) & " - " & VLOOKUP(U$1&"_"&$A8, Predicciones_Master!$A$4:$Q$2000, 8, FALSE), "N/A") | V8: =IF($D8="Por Jugar", "", IFERROR(VLOOKUP(U$1&"_"&$A8, Predicciones_Master!$A$4:$Q$2000, 11, FALSE), 0)) | W8: =IFERROR(VLOOKUP(W$1&"_"&$A8, Predicciones_Master!$A$4:$Q$2000, 7, FALSE) & " - " & VLOOKUP(W$1&"_"&$A8, Predicciones_Master!$A$4:$Q$2000, 8, FALSE), "N/A") | X8: =IF($D8="Por Jugar", "", IFERROR(VLOOKUP(W$1&"_"&$A8, Predicciones_Master!$A$4:$Q$2000, 11, FALSE), 0))
A9: =Resultados_Reales!A9 | B9: =Resultados_Reales!B9 | C9: =Resultados_Reales!C9 & " vs " & Resultados_Reales!D9 | D9: =IF(OR(Resultados_Reales!E9="", Resultados_Reales!F9=""), "Por Jugar", Resultados_Reales!E9 & " - " & Resultados_Reales!F9) | E9: =IFERROR(VLOOKUP(E$1&"_"&$A9, Predicciones_Master!$A$4:$Q$2000, 7, FALSE) & " - " & VLOOKUP(E$1&"_"&$A9, Predicciones_Master!$A$4:$Q$2000, 8, FALSE), "N/A") | F9: =IF($D9="Por Jugar", "", IFERROR(VLOOKUP(E$1&"_"&$A9, Predicciones_Master!$A$4:$Q$2000, 11, FALSE), 0)) | G9: =IFERROR(VLOOKUP(G$1&"_"&$A9, Predicciones_Master!$A$4:$Q$2000, 7, FALSE) & " - " & VLOOKUP(G$1&"_"&$A9, Predicciones_Master!$A$4:$Q$2000, 8, FALSE), "N/A") | H9: =IF($D9="Por Jugar", "", IFERROR(VLOOKUP(G$1&"_"&$A9, Predicciones_Master!$A$4:$Q$2000, 11, FALSE), 0)) | I9: =IFERROR(VLOOKUP(I$1&"_"&$A9, Predicciones_Master!$A$4:$Q$2000, 7, FALSE) & " - " & VLOOKUP(I$1&"_"&$A9, Predicciones_Master!$A$4:$Q$2000, 8, FALSE), "N/A") | J9: =IF($D9="Por Jugar", "", IFERROR(VLOOKUP(I$1&"_"&$A9, Predicciones_Master!$A$4:$Q$2000, 11, FALSE), 0)) | K9: =IFERROR(VLOOKUP(K$1&"_"&$A9, Predicciones_Master!$A$4:$Q$2000, 7, FALSE) & " - " & VLOOKUP(K$1&"_"&$A9, Predicciones_Master!$A$4:$Q$2000, 8, FALSE), "N/A") | L9: =IF($D9="Por Jugar", "", IFERROR(VLOOKUP(K$1&"_"&$A9, Predicciones_Master!$A$4:$Q$2000, 11, FALSE), 0)) | M9: =IFERROR(VLOOKUP(M$1&"_"&$A9, Predicciones_Master!$A$4:$Q$2000, 7, FALSE) & " - " & VLOOKUP(M$1&"_"&$A9, Predicciones_Master!$A$4:$Q$2000, 8, FALSE), "N/A") | N9: =IF($D9="Por Jugar", "", IFERROR(VLOOKUP(M$1&"_"&$A9, Predicciones_Master!$A$4:$Q$2000, 11, FALSE), 0)) | O9: =IFERROR(VLOOKUP(O$1&"_"&$A9, Predicciones_Master!$A$4:$Q$2000, 7, FALSE) & " - " & VLOOKUP(O$1&"_"&$A9, Predicciones_Master!$A$4:$Q$2000, 8, FALSE), "N/A") | P9: =IF($D9="Por Jugar", "", IFERROR(VLOOKUP(O$1&"_"&$A9, Predicciones_Master!$A$4:$Q$2000, 11, FALSE), 0)) | Q9: =IFERROR(VLOOKUP(Q$1&"_"&$A9, Predicciones_Master!$A$4:$Q$2000, 7, FALSE) & " - " & VLOOKUP(Q$1&"_"&$A9, Predicciones_Master!$A$4:$Q$2000, 8, FALSE), "N/A") | R9: =IF($D9="Por Jugar", "", IFERROR(VLOOKUP(Q$1&"_"&$A9, Predicciones_Master!$A$4:$Q$2000, 11, FALSE), 0)) | S9: =IFERROR(VLOOKUP(S$1&"_"&$A9, Predicciones_Master!$A$4:$Q$2000, 7, FALSE) & " - " & VLOOKUP(S$1&"_"&$A9, Predicciones_Master!$A$4:$Q$2000, 8, FALSE), "N/A") | T9: =IF($D9="Por Jugar", "", IFERROR(VLOOKUP(S$1&"_"&$A9, Predicciones_Master!$A$4:$Q$2000, 11, FALSE), 0)) | U9: =IFERROR(VLOOKUP(U$1&"_"&$A9, Predicciones_Master!$A$4:$Q$2000, 7, FALSE) & " - " & VLOOKUP(U$1&"_"&$A9, Predicciones_Master!$A$4:$Q$2000, 8, FALSE), "N/A") | V9: =IF($D9="Por Jugar", "", IFERROR(VLOOKUP(U$1&"_"&$A9, Predicciones_Master!$A$4:$Q$2000, 11, FALSE), 0)) | W9: =IFERROR(VLOOKUP(W$1&"_"&$A9, Predicciones_Master!$A$4:$Q$2000, 7, FALSE) & " - " & VLOOKUP(W$1&"_"&$A9, Predicciones_Master!$A$4:$Q$2000, 8, FALSE), "N/A") | X9: =IF($D9="Por Jugar", "", IFERROR(VLOOKUP(W$1&"_"&$A9, Predicciones_Master!$A$4:$Q$2000, 11, FALSE), 0))
A10: =Resultados_Reales!A10 | B10: =Resultados_Reales!B10 | C10: =Resultados_Reales!C10 & " vs " & Resultados_Reales!D10 | D10: =IF(OR(Resultados_Reales!E10="", Resultados_Reales!F10=""), "Por Jugar", Resultados_Reales!E10 & " - " & Resultados_Reales!F10) | E10: =IFERROR(VLOOKUP(E$1&"_"&$A10, Predicciones_Master!$A$4:$Q$2000, 7, FALSE) & " - " & VLOOKUP(E$1&"_"&$A10, Predicciones_Master!$A$4:$Q$2000, 8, FALSE), "N/A") | F10: =IF($D10="Por Jugar", "", IFERROR(VLOOKUP(E$1&"_"&$A10, Predicciones_Master!$A$4:$Q$2000, 11, FALSE), 0)) | G10: =IFERROR(VLOOKUP(G$1&"_"&$A10, Predicciones_Master!$A$4:$Q$2000, 7, FALSE) & " - " & VLOOKUP(G$1&"_"&$A10, Predicciones_Master!$A$4:$Q$2000, 8, FALSE), "N/A") | H10: =IF($D10="Por Jugar", "", IFERROR(VLOOKUP(G$1&"_"&$A10, Predicciones_Master!$A$4:$Q$2000, 11, FALSE), 0)) | I10: =IFERROR(VLOOKUP(I$1&"_"&$A10, Predicciones_Master!$A$4:$Q$2000, 7, FALSE) & " - " & VLOOKUP(I$1&"_"&$A10, Predicciones_Master!$A$4:$Q$2000, 8, FALSE), "N/A") | J10: =IF($D10="Por Jugar", "", IFERROR(VLOOKUP(I$1&"_"&$A10, Predicciones_Master!$A$4:$Q$2000, 11, FALSE), 0)) | K10: =IFERROR(VLOOKUP(K$1&"_"&$A10, Predicciones_Master!$A$4:$Q$2000, 7, FALSE) & " - " & VLOOKUP(K$1&"_"&$A10, Predicciones_Master!$A$4:$Q$2000, 8, FALSE), "N/A") | L10: =IF($D10="Por Jugar", "", IFERROR(VLOOKUP(K$1&"_"&$A10, Predicciones_Master!$A$4:$Q$2000, 11, FALSE), 0)) | M10: =IFERROR(VLOOKUP(M$1&"_"&$A10, Predicciones_Master!$A$4:$Q$2000, 7, FALSE) & " - " & VLOOKUP(M$1&"_"&$A10, Predicciones_Master!$A$4:$Q$2000, 8, FALSE), "N/A") | N10: =IF($D10="Por Jugar", "", IFERROR(VLOOKUP(M$1&"_"&$A10, Predicciones_Master!$A$4:$Q$2000, 11, FALSE), 0)) | O10: =IFERROR(VLOOKUP(O$1&"_"&$A10, Predicciones_Master!$A$4:$Q$2000, 7, FALSE) & " - " & VLOOKUP(O$1&"_"&$A10, Predicciones_Master!$A$4:$Q$2000, 8, FALSE), "N/A") | P10: =IF($D10="Por Jugar", "", IFERROR(VLOOKUP(O$1&"_"&$A10, Predicciones_Master!$A$4:$Q$2000, 11, FALSE), 0)) | Q10: =IFERROR(VLOOKUP(Q$1&"_"&$A10, Predicciones_Master!$A$4:$Q$2000, 7, FALSE) & " - " & VLOOKUP(Q$1&"_"&$A10, Predicciones_Master!$A$4:$Q$2000, 8, FALSE), "N/A") | R10: =IF($D10="Por Jugar", "", IFERROR(VLOOKUP(Q$1&"_"&$A10, Predicciones_Master!$A$4:$Q$2000, 11, FALSE), 0)) | S10: =IFERROR(VLOOKUP(S$1&"_"&$A10, Predicciones_Master!$A$4:$Q$2000, 7, FALSE) & " - " & VLOOKUP(S$1&"_"&$A10, Predicciones_Master!$A$4:$Q$2000, 8, FALSE), "N/A") | T10: =IF($D10="Por Jugar", "", IFERROR(VLOOKUP(S$1&"_"&$A10, Predicciones_Master!$A$4:$Q$2000, 11, FALSE), 0)) | U10: =IFERROR(VLOOKUP(U$1&"_"&$A10, Predicciones_Master!$A$4:$Q$2000, 7, FALSE) & " - " & VLOOKUP(U$1&"_"&$A10, Predicciones_Master!$A$4:$Q$2000, 8, FALSE), "N/A") | V10: =IF($D10="Por Jugar", "", IFERROR(VLOOKUP(U$1&"_"&$A10, Predicciones_Master!$A$4:$Q$2000, 11, FALSE), 0)) | W10: =IFERROR(VLOOKUP(W$1&"_"&$A10, Predicciones_Master!$A$4:$Q$2000, 7, FALSE) & " - " & VLOOKUP(W$1&"_"&$A10, Predicciones_Master!$A$4:$Q$2000, 8, FALSE), "N/A") | X10: =IF($D10="Por Jugar", "", IFERROR(VLOOKUP(W$1&"_"&$A10, Predicciones_Master!$A$4:$Q$2000, 11, FALSE), 0))
A11: =Resultados_Reales!A11 | B11: =Resultados_Reales!B11 | C11: =Resultados_Reales!C11 & " vs " & Resultados_Reales!D11 | D11: =IF(OR(Resultados_Reales!E11="", Resultados_Reales!F11=""), "Por Jugar", Resultados_Reales!E11 & " - " & Resultados_Reales!F11) | E11: =IFERROR(VLOOKUP(E$1&"_"&$A11, Predicciones_Master!$A$4:$Q$2000, 7, FALSE) & " - " & VLOOKUP(E$1&"_"&$A11, Predicciones_Master!$A$4:$Q$2000, 8, FALSE), "N/A") | F11: =IF($D11="Por Jugar", "", IFERROR(VLOOKUP(E$1&"_"&$A11, Predicciones_Master!$A$4:$Q$2000, 11, FALSE), 0)) | G11: =IFERROR(VLOOKUP(G$1&"_"&$A11, Predicciones_Master!$A$4:$Q$2000, 7, FALSE) & " - " & VLOOKUP(G$1&"_"&$A11, Predicciones_Master!$A$4:$Q$2000, 8, FALSE), "N/A") | H11: =IF($D11="Por Jugar", "", IFERROR(VLOOKUP(G$1&"_"&$A11, Predicciones_Master!$A$4:$Q$2000, 11, FALSE), 0)) | I11: =IFERROR(VLOOKUP(I$1&"_"&$A11, Predicciones_Master!$A$4:$Q$2000, 7, FALSE) & " - " & VLOOKUP(I$1&"_"&$A11, Predicciones_Master!$A$4:$Q$2000, 8, FALSE), "N/A") | J11: =IF($D11="Por Jugar", "", IFERROR(VLOOKUP(I$1&"_"&$A11, Predicciones_Master!$A$4:$Q$2000, 11, FALSE), 0)) | K11: =IFERROR(VLOOKUP(K$1&"_"&$A11, Predicciones_Master!$A$4:$Q$2000, 7, FALSE) & " - " & VLOOKUP(K$1&"_"&$A11, Predicciones_Master!$A$4:$Q$2000, 8, FALSE), "N/A") | L11: =IF($D11="Por Jugar", "", IFERROR(VLOOKUP(K$1&"_"&$A11, Predicciones_Master!$A$4:$Q$2000, 11, FALSE), 0)) | M11: =IFERROR(VLOOKUP(M$1&"_"&$A11, Predicciones_Master!$A$4:$Q$2000, 7, FALSE) & " - " & VLOOKUP(M$1&"_"&$A11, Predicciones_Master!$A$4:$Q$2000, 8, FALSE), "N/A") | N11: =IF($D11="Por Jugar", "", IFERROR(VLOOKUP(M$1&"_"&$A11, Predicciones_Master!$A$4:$Q$2000, 11, FALSE), 0)) | O11: =IFERROR(VLOOKUP(O$1&"_"&$A11, Predicciones_Master!$A$4:$Q$2000, 7, FALSE) & " - " & VLOOKUP(O$1&"_"&$A11, Predicciones_Master!$A$4:$Q$2000, 8, FALSE), "N/A") | P11: =IF($D11="Por Jugar", "", IFERROR(VLOOKUP(O$1&"_"&$A11, Predicciones_Master!$A$4:$Q$2000, 11, FALSE), 0)) | Q11: =IFERROR(VLOOKUP(Q$1&"_"&$A11, Predicciones_Master!$A$4:$Q$2000, 7, FALSE) & " - " & VLOOKUP(Q$1&"_"&$A11, Predicciones_Master!$A$4:$Q$2000, 8, FALSE), "N/A") | R11: =IF($D11="Por Jugar", "", IFERROR(VLOOKUP(Q$1&"_"&$A11, Predicciones_Master!$A$4:$Q$2000, 11, FALSE), 0)) | S11: =IFERROR(VLOOKUP(S$1&"_"&$A11, Predicciones_Master!$A$4:$Q$2000, 7, FALSE) & " - " & VLOOKUP(S$1&"_"&$A11, Predicciones_Master!$A$4:$Q$2000, 8, FALSE), "N/A") | T11: =IF($D11="Por Jugar", "", IFERROR(VLOOKUP(S$1&"_"&$A11, Predicciones_Master!$A$4:$Q$2000, 11, FALSE), 0)) | U11: =IFERROR(VLOOKUP(U$1&"_"&$A11, Predicciones_Master!$A$4:$Q$2000, 7, FALSE) & " - " & VLOOKUP(U$1&"_"&$A11, Predicciones_Master!$A$4:$Q$2000, 8, FALSE), "N/A") | V11: =IF($D11="Por Jugar", "", IFERROR(VLOOKUP(U$1&"_"&$A11, Predicciones_Master!$A$4:$Q$2000, 11, FALSE), 0)) | W11: =IFERROR(VLOOKUP(W$1&"_"&$A11, Predicciones_Master!$A$4:$Q$2000, 7, FALSE) & " - " & VLOOKUP(W$1&"_"&$A11, Predicciones_Master!$A$4:$Q$2000, 8, FALSE), "N/A") | X11: =IF($D11="Por Jugar", "", IFERROR(VLOOKUP(W$1&"_"&$A11, Predicciones_Master!$A$4:$Q$2000, 11, FALSE), 0))
A12: =Resultados_Reales!A12 | B12: =Resultados_Reales!B12 | C12: =Resultados_Reales!C12 & " vs " & Resultados_Reales!D12 | D12: =IF(OR(Resultados_Reales!E12="", Resultados_Reales!F12=""), "Por Jugar", Resultados_Reales!E12 & " - " & Resultados_Reales!F12) | E12: =IFERROR(VLOOKUP(E$1&"_"&$A12, Predicciones_Master!$A$4:$Q$2000, 7, FALSE) & " - " & VLOOKUP(E$1&"_"&$A12, Predicciones_Master!$A$4:$Q$2000, 8, FALSE), "N/A") | F12: =IF($D12="Por Jugar", "", IFERROR(VLOOKUP(E$1&"_"&$A12, Predicciones_Master!$A$4:$Q$2000, 11, FALSE), 0)) | G12: =IFERROR(VLOOKUP(G$1&"_"&$A12, Predicciones_Master!$A$4:$Q$2000, 7, FALSE) & " - " & VLOOKUP(G$1&"_"&$A12, Predicciones_Master!$A$4:$Q$2000, 8, FALSE), "N/A") | H12: =IF($D12="Por Jugar", "", IFERROR(VLOOKUP(G$1&"_"&$A12, Predicciones_Master!$A$4:$Q$2000, 11, FALSE), 0)) | I12: =IFERROR(VLOOKUP(I$1&"_"&$A12, Predicciones_Master!$A$4:$Q$2000, 7, FALSE) & " - " & VLOOKUP(I$1&"_"&$A12, Predicciones_Master!$A$4:$Q$2000, 8, FALSE), "N/A") | J12: =IF($D12="Por Jugar", "", IFERROR(VLOOKUP(I$1&"_"&$A12, Predicciones_Master!$A$4:$Q$2000, 11, FALSE), 0)) | K12: =IFERROR(VLOOKUP(K$1&"_"&$A12, Predicciones_Master!$A$4:$Q$2000, 7, FALSE) & " - " & VLOOKUP(K$1&"_"&$A12, Predicciones_Master!$A$4:$Q$2000, 8, FALSE), "N/A") | L12: =IF($D12="Por Jugar", "", IFERROR(VLOOKUP(K$1&"_"&$A12, Predicciones_Master!$A$4:$Q$2000, 11, FALSE), 0)) | M12: =IFERROR(VLOOKUP(M$1&"_"&$A12, Predicciones_Master!$A$4:$Q$2000, 7, FALSE) & " - " & VLOOKUP(M$1&"_"&$A12, Predicciones_Master!$A$4:$Q$2000, 8, FALSE), "N/A") | N12: =IF($D12="Por Jugar", "", IFERROR(VLOOKUP(M$1&"_"&$A12, Predicciones_Master!$A$4:$Q$2000, 11, FALSE), 0)) | O12: =IFERROR(VLOOKUP(O$1&"_"&$A12, Predicciones_Master!$A$4:$Q$2000, 7, FALSE) & " - " & VLOOKUP(O$1&"_"&$A12, Predicciones_Master!$A$4:$Q$2000, 8, FALSE), "N/A") | P12: =IF($D12="Por Jugar", "", IFERROR(VLOOKUP(O$1&"_"&$A12, Predicciones_Master!$A$4:$Q$2000, 11, FALSE), 0)) | Q12: =IFERROR(VLOOKUP(Q$1&"_"&$A12, Predicciones_Master!$A$4:$Q$2000, 7, FALSE) & " - " & VLOOKUP(Q$1&"_"&$A12, Predicciones_Master!$A$4:$Q$2000, 8, FALSE), "N/A") | R12: =IF($D12="Por Jugar", "", IFERROR(VLOOKUP(Q$1&"_"&$A12, Predicciones_Master!$A$4:$Q$2000, 11, FALSE), 0)) | S12: =IFERROR(VLOOKUP(S$1&"_"&$A12, Predicciones_Master!$A$4:$Q$2000, 7, FALSE) & " - " & VLOOKUP(S$1&"_"&$A12, Predicciones_Master!$A$4:$Q$2000, 8, FALSE), "N/A") | T12: =IF($D12="Por Jugar", "", IFERROR(VLOOKUP(S$1&"_"&$A12, Predicciones_Master!$A$4:$Q$2000, 11, FALSE), 0)) | U12: =IFERROR(VLOOKUP(U$1&"_"&$A12, Predicciones_Master!$A$4:$Q$2000, 7, FALSE) & " - " & VLOOKUP(U$1&"_"&$A12, Predicciones_Master!$A$4:$Q$2000, 8, FALSE), "N/A") | V12: =IF($D12="Por Jugar", "", IFERROR(VLOOKUP(U$1&"_"&$A12, Predicciones_Master!$A$4:$Q$2000, 11, FALSE), 0)) | W12: =IFERROR(VLOOKUP(W$1&"_"&$A12, Predicciones_Master!$A$4:$Q$2000, 7, FALSE) & " - " & VLOOKUP(W$1&"_"&$A12, Predicciones_Master!$A$4:$Q$2000, 8, FALSE), "N/A") | X12: =IF($D12="Por Jugar", "", IFERROR(VLOOKUP(W$1&"_"&$A12, Predicciones_Master!$A$4:$Q$2000, 11, FALSE), 0))
A13: =Resultados_Reales!A13 | B13: =Resultados_Reales!B13 | C13: =Resultados_Reales!C13 & " vs " & Resultados_Reales!D13 | D13: =IF(OR(Resultados_Reales!E13="", Resultados_Reales!F13=""), "Por Jugar", Resultados_Reales!E13 & " - " & Resultados_Reales!F13) | E13: =IFERROR(VLOOKUP(E$1&"_"&$A13, Predicciones_Master!$A$4:$Q$2000, 7, FALSE) & " - " & VLOOKUP(E$1&"_"&$A13, Predicciones_Master!$A$4:$Q$2000, 8, FALSE), "N/A") | F13: =IF($D13="Por Jugar", "", IFERROR(VLOOKUP(E$1&"_"&$A13, Predicciones_Master!$A$4:$Q$2000, 11, FALSE), 0)) | G13: =IFERROR(VLOOKUP(G$1&"_"&$A13, Predicciones_Master!$A$4:$Q$2000, 7, FALSE) & " - " & VLOOKUP(G$1&"_"&$A13, Predicciones_Master!$A$4:$Q$2000, 8, FALSE), "N/A") | H13: =IF($D13="Por Jugar", "", IFERROR(VLOOKUP(G$1&"_"&$A13, Predicciones_Master!$A$4:$Q$2000, 11, FALSE), 0)) | I13: =IFERROR(VLOOKUP(I$1&"_"&$A13, Predicciones_Master!$A$4:$Q$2000, 7, FALSE) & " - " & VLOOKUP(I$1&"_"&$A13, Predicciones_Master!$A$4:$Q$2000, 8, FALSE), "N/A") | J13: =IF($D13="Por Jugar", "", IFERROR(VLOOKUP(I$1&"_"&$A13, Predicciones_Master!$A$4:$Q$2000, 11, FALSE), 0)) | K13: =IFERROR(VLOOKUP(K$1&"_"&$A13, Predicciones_Master!$A$4:$Q$2000, 7, FALSE) & " - " & VLOOKUP(K$1&"_"&$A13, Predicciones_Master!$A$4:$Q$2000, 8, FALSE), "N/A") | L13: =IF($D13="Por Jugar", "", IFERROR(VLOOKUP(K$1&"_"&$A13, Predicciones_Master!$A$4:$Q$2000, 11, FALSE), 0)) | M13: =IFERROR(VLOOKUP(M$1&"_"&$A13, Predicciones_Master!$A$4:$Q$2000, 7, FALSE) & " - " & VLOOKUP(M$1&"_"&$A13, Predicciones_Master!$A$4:$Q$2000, 8, FALSE), "N/A") | N13: =IF($D13="Por Jugar", "", IFERROR(VLOOKUP(M$1&"_"&$A13, Predicciones_Master!$A$4:$Q$2000, 11, FALSE), 0)) | O13: =IFERROR(VLOOKUP(O$1&"_"&$A13, Predicciones_Master!$A$4:$Q$2000, 7, FALSE) & " - " & VLOOKUP(O$1&"_"&$A13, Predicciones_Master!$A$4:$Q$2000, 8, FALSE), "N/A") | P13: =IF($D13="Por Jugar", "", IFERROR(VLOOKUP(O$1&"_"&$A13, Predicciones_Master!$A$4:$Q$2000, 11, FALSE), 0)) | Q13: =IFERROR(VLOOKUP(Q$1&"_"&$A13, Predicciones_Master!$A$4:$Q$2000, 7, FALSE) & " - " & VLOOKUP(Q$1&"_"&$A13, Predicciones_Master!$A$4:$Q$2000, 8, FALSE), "N/A") | R13: =IF($D13="Por Jugar", "", IFERROR(VLOOKUP(Q$1&"_"&$A13, Predicciones_Master!$A$4:$Q$2000, 11, FALSE), 0)) | S13: =IFERROR(VLOOKUP(S$1&"_"&$A13, Predicciones_Master!$A$4:$Q$2000, 7, FALSE) & " - " & VLOOKUP(S$1&"_"&$A13, Predicciones_Master!$A$4:$Q$2000, 8, FALSE), "N/A") | T13: =IF($D13="Por Jugar", "", IFERROR(VLOOKUP(S$1&"_"&$A13, Predicciones_Master!$A$4:$Q$2000, 11, FALSE), 0)) | U13: =IFERROR(VLOOKUP(U$1&"_"&$A13, Predicciones_Master!$A$4:$Q$2000, 7, FALSE) & " - " & VLOOKUP(U$1&"_"&$A13, Predicciones_Master!$A$4:$Q$2000, 8, FALSE), "N/A") | V13: =IF($D13="Por Jugar", "", IFERROR(VLOOKUP(U$1&"_"&$A13, Predicciones_Master!$A$4:$Q$2000, 11, FALSE), 0)) | W13: =IFERROR(VLOOKUP(W$1&"_"&$A13, Predicciones_Master!$A$4:$Q$2000, 7, FALSE) & " - " & VLOOKUP(W$1&"_"&$A13, Predicciones_Master!$A$4:$Q$2000, 8, FALSE), "N/A") | X13: =IF($D13="Por Jugar", "", IFERROR(VLOOKUP(W$1&"_"&$A13, Predicciones_Master!$A$4:$Q$2000, 11, FALSE), 0))
